Workbook

Sheet changes made
B2: date | C2: edits
B3: 46099 | C3: "calculations" tab 1. addition of annual interest columns 2. replaced formulas for all of cummulative balances (col Y - AB) 3. edited formula for the reference table of BRS, FRS and ERS (AG7:AI7) "output for phase 1" tab 1. edited formula for eligibility checks (D26, D28, D30)
B4: 46100 | C4: "output for phase 1" 1. change heading of "options for retirement sum" to "options for retirement sum at [toggle]" - toggle options: "55", "65",["66","67","68","69","70"] - add explanation behind the toggle age - for 66-70, only include the age where they choose to start receiving life payouts 55: age where you choose your retirement sum 65: age where you make a final decision on your retirement sum 66-70: age where you choose to start receiving LIFE payouts 2. merge the 2 tables of projected retirement sums at 65 and 70 into 1 using toggle for age "retirement sum needed" 1. added amt needed (PV) in cell A8, B8
B5: 46107 | C5: "output for phase 1" 1. options for retirement sum graph to not include MA in the total CPF savings

Sheet questions
A2: Q1 | B2: current age | C2: =(TODAY()-C3)/365 -> 27.391781 | E2: retrieve from db/my info
A3: Q1a | B3: birth date | C3: 36110 | E3: client to fill in
A4: Q1b | B4: year when age 55 | C4: =YEAR(C3)+55 -> 2053 | E4: calculate from client's info
A5: Q1c | B5: year when age 65 | C5: =YEAR(C3)+65 -> 2063 | E5: no fill, just a header
A6: Q2 | B6: age intend to retire | C6: 60
A7: Q3 | B7: monthly income required to retire | C7: 5500
A8: Q4 | B8: age expectancy | C8: 85
A9: Q5 | B9: current wage
A10: Q5a | B10: monthly income | C10: 10000
A11: Q5b | B11: bonus (months) | C11: 1
A12: Q5c | B12: yearly increment | C12: 0.03
A13: Q6 | B13: years till retirement | C13: =C6-C2 -> 32.608219
A14: Q7 | B14: current cpf balances
A15: Q7a | B15: OA | C15: 7500
A16: Q7b | B16: SA | C16: 2500
A17: Q7c | B17: MA | C17: 2500
A18: Q8 | B18: using OA for mortgage | C18: yes
A19: Q8a | B19: date when mortgage is fully paid | C19: 53206
A20: Q8b | B20: how much mortgage | C20: 700
A21: Q9 | B21: do you own a property with a remaining lease until at least age 95 | C21: yes

Sheet calculations
A1: date | B1: age | C1: current income | D1: Additional income | E1: cpf allocation cap check | G1: cpf allocation | L1: cpf withdrawal | M1: interest | S1: extra interest | Y1: cummulative balance | AC1: projected retirement sum
E2: ordinary wage | F2: additional wage | G2: Total Contribution | H2: OA | I2: SA | J2: MA | K2: RA | L2: OA - mortgage | M2: OA | N2: SA/RA | O2: MA | P2: OA annual | Q2: SA/RA annual | R2: MA annual | S2: OA | T2: SA/RA | U2: MA | V2: OA annual | W2: SA/RA annual | X2: MA annual | Y2: OA | Z2: SA | AA2: MA | AB2: RA | AC2: BRS | AD2: FRS | AE2: ERS
A3: =EOMONTH(today(),0) -> 46112 | B3: =round(YEARFRAC(EOMONTH(questions!$C$3, 0),A3,1),2) -> 27.33 | C3: =if(B3<questions!C6,questions!C10,0) -> 10000 | D3: =IF(MONTH(A3)=12,C3*questions!$C$11,0) -> 0 | E3: =MIN(C3,IF(YEAR(A3)=2025,7600,8000)) -> 8000 | F3: =MIN(102000-E3*12,D3) -> 0 | G3: {=if(YEAR(A3)=2025,XLOOKUP(B3,Lookup!$A$3:$A$7,Lookup!$D$3:$D$7,,1)*SUM(E3:F3), XLOOKUP(B3,Lookup!$A$14:$A$18,Lookup!$D$14:$D$18,,1)*SUM(E3:F3))} -> 2960 | H3: {=if(YEAR(A3)=2025,XLOOKUP(B3,Lookup!$F$3:$F$10,Lookup!$G$3:$G$10,,1)*G3, XLOOKUP(B3,Lookup!$F$14:$F$21,Lookup!$G$14:$G$21,,1)*G3)} -> 1840.232 | I3: {=if(B3<55, if(YEAR(A3)=2025,XLOOKUP(B3,Lookup!$F$3:$F$10,Lookup!$H$3:$H$10,,1)*G3, XLOOKUP(B3,Lookup!$F$14:$F$21,Lookup!$H$14:$H$21,,1)*G3),0)} -> 479.816 | J3: {=if(YEAR(A3)=2025,XLOOKUP(B3,Lookup!$F$3:$F$10,Lookup!$I$3:$I$10,,1)*G3, XLOOKUP(B3,Lookup!$F$14:$F$21,Lookup!$I$14:$I$21,,1)*G3)} -> 639.952 | K3: {=if(B3>54, if(YEAR(A3)=2025,XLOOKUP(B3,Lookup!$F$3:$F$10,Lookup!$H$3:$H$10,,1)*G3, XLOOKUP(B3,Lookup!$F$14:$F$21,Lookup!$H$14:$H$21,,1)*G3),0)} -> 0 | L3: =IF(and(A3<questions!$C$19,questions!$C$18="yes"),questions!$C$20,0) -> 700 | M3: =(questions!$C$15+H3)*Lookup!A$26/12 -> 19.458817 | N3: =(questions!$C$16+I3)*Lookup!B$26/12 -> 9.93272 | O3: =(questions!$C$17+J3)*Lookup!C$26/12 -> 10.466507 | P3: =IF(year($A3)=year($A2), P2+M3, M3) -> 19.458817 | Q3: =IF(year(A3)=year(A2), Q2+N3, N3) -> 9.93272 | R3: =IF(year(A3)=year(A2), R2+O3, O3) -> 10.466507 | S3: =min(20000,questions!C15)*0.01/12 -> 6.25 | T3: =min(60000-min(20000,questions!C15),questions!C16)*0.01/12 -> 2.0833333 | U3: =min(60000-min(60000-min(20000,questions!C15),questions!C16)-min(20000,questions!C15),questions!C17)*0.01/12 -> 2.0833333 | V3: =IF(year($A3)=year($A2), V2+S3, S3) -> 6.25 | W3: =IF(year($A3)=year($A2), W2+T3, T3) -> 2.0833333 | X3: =IF(year($A3)=year($A2), X2+U3, U3) -> 2.0833333 | Y3: =if(month($A3)=12,max(0,questions!C15+H3+P3+V3-L3),max(0,questions!C15+H3-L3)) -> 8640.232 | Z3: =if(month($A3)=12,max(0,questions!C16+I3+Q3+W3),max(0,questions!C16+I3)) -> 2979.816 | AA3: =if(month($A3)=12,max(0,questions!C17+J3+R3+X3),max(0,questions!C17+J3)) -> 3139.952 | AB3: =if(month($A3)=12,max(0,questions!C16+K3+Q3+W3),max(0,questions!C16+K3)) -> 2500 | AC3: {=IFS(B3<66, XLOOKUP(year(A3),Lookup!$K$13:$K1000,Lookup!$L$13:$L1000,"missing",,1),B3>65,XLOOKUP(questions!$C$5,Lookup!$K$13:$K1000,Lookup!$L$13:$L1000,"missing",,1))} -> 110200 | AD3: {=IFS(B3<66, XLOOKUP(year(A3),Lookup!$K$13:$K1000,Lookup!$M$13:$M1000,"missing",,1),B3>65, XLOOKUP(questions!$C$5,Lookup!$K$13:$K1000,Lookup!$M$13:$M1000,"missing",,1))} -> 220400 | AE3: {=IFS(B3<66, XLOOKUP(year(A3),Lookup!$K$13:$K1000,Lookup!$N$13:$N1000,"missing",,1),B3>65,XLOOKUP(questions!$C$5,Lookup!$K$13:$K1000,Lookup!$N$13:$N1000,"missing",,1))} -> 440800
A4: =eomonth(EDATE(A3,1),0) -> 46142 | B4: =round(YEARFRAC(EOMONTH(questions!$C$3, 0),A4,1),2) -> 27.41 | C4: =IF(B4<questions!$C$6,if(MONTH(A4)=1,C3*(1+questions!$C$12),C3),0) -> 10000 | D4: =IF(MONTH(A4)=12,C4*questions!$C$11,0) -> 0 | E4: =MIN(C4,IF(YEAR(A4)=2025,7600,8000)) -> 8000 | F4: =MIN(102000-E4*12,D4) -> 0 | G4: {=if(YEAR(A4)=2025,XLOOKUP(B4,Lookup!$A$3:$A$7,Lookup!$D$3:$D$7,,1)*SUM(E4:F4), XLOOKUP(B4,Lookup!$A$14:$A$18,Lookup!$D$14:$D$18,,1)*SUM(E4:F4))} -> 2960 | H4: {=if(YEAR(A4)=2025,XLOOKUP(B4,Lookup!$F$3:$F$10,Lookup!$G$3:$G$10,,1)*G4, XLOOKUP(B4,Lookup!$F$14:$F$21,Lookup!$G$14:$G$21,,1)*G4)} -> 1840.232 | I4: {=if(B4<55, if(YEAR(A4)=2025,XLOOKUP(B4,Lookup!$F$3:$F$10,Lookup!$H$3:$H$10,,1)*G4, XLOOKUP(B4,Lookup!$F$14:$F$21,Lookup!$H$14:$H$21,,1)*G4),0)} -> 479.816 | J4: {=if(YEAR(A4)=2025,XLOOKUP(B4,Lookup!$F$3:$F$10,Lookup!$I$3:$I$10,,1)*G4, XLOOKUP(B4,Lookup!$F$14:$F$21,Lookup!$I$14:$I$21,,1)*G4)} -> 639.952 | K4: {=if(B4>54, if(YEAR(A4)=2025,XLOOKUP(B4,Lookup!$F$3:$F$10,Lookup!$H$3:$H$10,,1)*G4, XLOOKUP(B4,Lookup!$F$14:$F$21,Lookup!$H$14:$H$21,,1)*G4),0)} -> 0 | L4: =IF(and(A4<questions!$C$19,questions!$C$18="yes"),questions!$C$20,0) -> 700 | M4: =(Y3+H4)*Lookup!A$26/12 -> 21.8343 | N4: =if(B4<55, (Z3+I4)*Lookup!B$26/12, (AB3+K4)*Lookup!B$26/12) -> 11.532107 | O4: =(AA3+J4)*Lookup!C$26/12 -> 12.59968 | P4: =IF(year(A4)=year(A3), P3+M4, M4) -> 41.293117 | Q4: =IF(year(A4)=year(A3), Q3+N4, N4) -> 21.464827 | R4: =IF(year(A4)=year(A3), R3+O4, O4) -> 23.066187 | S4: =if(B4<55,min(20000,Y3)*0.01/12,min(20000,Y3)*0.02/12) -> 7.2001933 | T4: =if(B4<=55,min(60000-min(20000,Y3),Z3)*0.01/12,min(30000-min(20000,Y3),AB3)*0.02/12+min(30000,AB3)*0.01/12) -> 2.48318 | U4: =if(B4<55,min(60000-min(60000-min(20000,Y3),Z3)-min(20000,Y3),AA3)*0.01/12,min(30000-min(30000-min(20000,Y3),AB3)-min(20000,Y3),AA3)*0.02/12+min(30000-min(30000-min(20000,Y3),AB3)-min(20000,Y3),AA3)*0.01/12) -> 2.6166267 | V4: =IF(year($A4)=year($A3), V3+S4, S4) -> 13.450193 | W4: =IF(year($A4)=year($A3), W3+T4, T4) -> 4.5665133 | X4: =IF(year($A4)=year($A3), X3+U4, U4) -> 4.69996 | Y4: =IFS( B4<55, MAX( Y3 + IF(MONTH(A4)=12, P4+V4, 0) + H4 - L4 + MAX(0, IF(AA3 >= VLOOKUP(YEAR(A4), Lookup!$Q:$R, 2), Z3 + IF(MONTH(A4)=12, Q4+W4, 0) + I4 + AA3 + IF(MONTH(A4)=12, R4+X4, 0) - VLOOKUP(YEAR(A4), Lookup!$Q:$R, 2) + J4, Z3 + IF(MONTH(A4)=12, Q4+W4, 0) + I4 ) - VLOOKUP(YEAR(A4), Lookup!$K:$M, 3) ), 0), B4=55, IF(Z3>=AD4, MAX(Y3 + IF(MONTH(A4)=12, P4+V4, 0) + H4 - L4, 0), MAX(MAX(0, Y3-(AD4-Z3)) + IF(MONTH(A4)=12, P4+V4, 0) + H4 - L4, 0) ), B4>55, IF(AB3>=$AH$7, MAX(Y3 + IF(MONTH(A4)=12, P4+V4, 0) + H4 - L4 + K4 + Z3, 0), MAX(Y3 + IF(MONTH(A4)=12, P4+V4, 0) + H4 - L4, 0) ) ) -> 9780.464 | Z4: =IFS( B4<55, MIN( IF(AA3 >= VLOOKUP(YEAR(A4), Lookup!$Q:$R, 2), Z3 + IF(MONTH(A4)=12, Q4+W4, 0) + I4 + AA3 + IF(MONTH(A4)=12, R4+X4, 0) - VLOOKUP(YEAR(A4), Lookup!$Q:$R, 2) + J4, Z3 + IF(MONTH(A4)=12, Q4+W4, 0) + I4 ), VLOOKUP(YEAR(A4), Lookup!$K:$M, 3) ), B4=55, IF(Z3 >= AD4, Z3 - AD4, 0), B4>55, 0 ) -> 3459.632 | AA4: =IFS( B4<65, IF(AA3+J4 < VLOOKUP(YEAR(A4), Lookup!$Q:$R, 2), AA3 + IF(MONTH(A4)=12, R3+X3, 0) + J4, MIN( AA3 + IF(MONTH(A4)=12, R3+X3, 0) + J4 , VLOOKUP(YEAR(A4), Lookup!$Q:$R, 2) ) ), B4>=65, IF(AA3+J4 < VLOOKUP(questions!$C$5, Lookup!$Q:$R, 2), AA3 + IF(MONTH(A4)=12, R3+X3, 0) + J4 , MIN( AA3 + IF(MONTH(A4)=12, R3+X3, 0) + J4, VLOOKUP(questions!$C$5, Lookup!$Q:$R, 2) ) ) ) -> 3779.904 | AB4: =IFS( B4<55, 0, B4=55, MIN(Y3+Z3, AD4), B4>55, IF(AB3 < $AH$7, MIN(AB3 + IF(MONTH(A4)=12, Q4+W4, 0) + K4, $AH$7), AB3 + IF(MONTH(A4)=12, Q4+W4, 0) + K4 ) ) -> 0 | AC4: {=IFS(B4<66, XLOOKUP(year(A4),Lookup!$K$13:$K1000,Lookup!$L$13:$L1000,"missing",,1),B4>65,XLOOKUP(questions!$C$5,Lookup!$K$13:$K1000,Lookup!$L$13:$L1000,"missing",,1))} -> 110200 | AD4: {=IFS(B4<66, XLOOKUP(year(A4),Lookup!$K$13:$K1000,Lookup!$M$13:$M1000,"missing",,1),B4>65, XLOOKUP(questions!$C$5,Lookup!$K$13:$K1000,Lookup!$M$13:$M1000,"missing",,1))} -> 220400 | AE4: {=IFS(B4<66, XLOOKUP(year(A4),Lookup!$K$13:$K1000,Lookup!$N$13:$N1000,"missing",,1),B4>65,XLOOKUP(questions!$C$5,Lookup!$K$13:$K1000,Lookup!$N$13:$N1000,"missing",,1))} -> 440800 | AG4: {=INDEX(calculations!Y:Y, XLOOKUP(55,calculations!B:B,row(calculations!Y:Y)) - 1)} -> 641964.18 | AH4: {=INDEX(calculations!Z:Z, XLOOKUP(55,calculations!B:B,row(calculations!Z:Z)) - 1)} -> 549331.94 | AI4: {=INDEX(calculations!AA:AA, XLOOKUP(55,calculations!B:B,row(calculations!AA:AA)) - 1)} -> 199993.8 | AJ4: =SUM(AG4:AH4) -> 1191296.1
A5: =eomonth(EDATE(A4,1),0) -> 46173 | B5: =round(YEARFRAC(EOMONTH(questions!$C$3, 0),A5,1),2) -> 27.5 | C5: =IF(B5<questions!$C$6,if(MONTH(A5)=1,C4*(1+questions!$C$12),C4),0) -> 10000 | D5: =IF(MONTH(A5)=12,C5*questions!$C$11,0) -> 0 | E5: =MIN(C5,IF(YEAR(A5)=2025,7600,8000)) -> 8000 | F5: =MIN(102000-E5*12,D5) -> 0 | G5: {=if(YEAR(A5)=2025,XLOOKUP(B5,Lookup!$A$3:$A$7,Lookup!$D$3:$D$7,,1)*SUM(E5:F5), XLOOKUP(B5,Lookup!$A$14:$A$18,Lookup!$D$14:$D$18,,1)*SUM(E5:F5))} -> 2960 | H5: {=if(YEAR(A5)=2025,XLOOKUP(B5,Lookup!$F$3:$F$10,Lookup!$G$3:$G$10,,1)*G5, XLOOKUP(B5,Lookup!$F$14:$F$21,Lookup!$G$14:$G$21,,1)*G5)} -> 1840.232 | I5: {=if(B5<55, if(YEAR(A5)=2025,XLOOKUP(B5,Lookup!$F$3:$F$10,Lookup!$H$3:$H$10,,1)*G5, XLOOKUP(B5,Lookup!$F$14:$F$21,Lookup!$H$14:$H$21,,1)*G5),0)} -> 479.816 | J5: {=if(YEAR(A5)=2025,XLOOKUP(B5,Lookup!$F$3:$F$10,Lookup!$I$3:$I$10,,1)*G5, XLOOKUP(B5,Lookup!$F$14:$F$21,Lookup!$I$14:$I$21,,1)*G5)} -> 639.952 | K5: {=if(B5>54, if(YEAR(A5)=2025,XLOOKUP(B5,Lookup!$F$3:$F$10,Lookup!$H$3:$H$10,,1)*G5, XLOOKUP(B5,Lookup!$F$14:$F$21,Lookup!$H$14:$H$21,,1)*G5),0)} -> 0 | L5: =IF(and(A5<questions!$C$19,questions!$C$18="yes"),questions!$C$20,0) -> 700 | M5: =(Y4+H5)*Lookup!A$26/12 -> 24.209783 | N5: =if(B5<55, (Z4+I5)*Lookup!B$26/12, (AB4+K5)*Lookup!B$26/12) -> 13.131493 | O5: =(AA4+J5)*Lookup!C$26/12 -> 14.732853 | P5: =IF(year(A5)=year(A4), P4+M5, M5) -> 65.5029 | Q5: =IF(year(A5)=year(A4), Q4+N5, N5) -> 34.59632 | R5: =IF(year(A5)=year(A4), R4+O5, O5) -> 37.79904 | S5: =if(B5<55,min(20000,Y4)*0.01/12,min(20000,Y4)*0.02/12) -> 8.1503867 | T5: =if(B5<=55,min(60000-min(20000,Y4),Z4)*0.01/12,min(30000-min(20000,Y4),AB4)*0.02/12+min(30000,AB4)*0.01/12) -> 2.8830267 | U5: =if(B5<55,min(60000-min(60000-min(20000,Y4),Z4)-min(20000,Y4),AA4)*0.01/12,min(30000-min(30000-min(20000,Y4),AB4)-min(20000,Y4),AA4)*0.02/12+min(30000-min(30000-min(20000,Y4),AB4)-min(20000,Y4),AA4)*0.01/12) -> 3.14992 | V5: =IF(year($A5)=year($A4), V4+S5, S5) -> 21.60058 | W5: =IF(year($A5)=year($A4), W4+T5, T5) -> 7.44954 | X5: =IF(year($A5)=year($A4), X4+U5, U5) -> 7.84988 | Y5: =IFS( B5<55, MAX( Y4 + IF(MONTH(A5)=12, P5+V5, 0) + H5 - L5 + MAX(0, IF(AA4 >= VLOOKUP(YEAR(A5), Lookup!$Q:$R, 2), Z4 + IF(MONTH(A5)=12, Q5+W5, 0) + I5 + AA4 + IF(MONTH(A5)=12, R5+X5, 0) - VLOOKUP(YEAR(A5), Lookup!$Q:$R, 2) + J5, Z4 + IF(MONTH(A5)=12, Q5+W5, 0) + I5 ) - VLOOKUP(YEAR(A5), Lookup!$K:$M, 3) ), 0), B5=55, IF(Z4>=AD5, MAX(Y4 + IF(MONTH(A5)=12, P5+V5, 0) + H5 - L5, 0), MAX(MAX(0, Y4-(AD5-Z4)) + IF(MONTH(A5)=12, P5+V5, 0) + H5 - L5, 0) ), B5>55, IF(AB4>=$AH$7, MAX(Y4 + IF(MONTH(A5)=12, P5+V5, 0) + H5 - L5 + K5 + Z4, 0), MAX(Y4 + IF(MONTH(A5)=12, P5+V5, 0) + H5 - L5, 0) ) ) -> 10920.696 | Z5: =IFS( B5<55, MIN( IF(AA4 >= VLOOKUP(YEAR(A5), Lookup!$Q:$R, 2), Z4 + IF(MONTH(A5)=12, Q5+W5, 0) + I5 + AA4 + IF(MONTH(A5)=12, R5+X5, 0) - VLOOKUP(YEAR(A5), Lookup!$Q:$R, 2) + J5, Z4 + IF(MONTH(A5)=12, Q5+W5, 0) + I5 ), VLOOKUP(YEAR(A5), Lookup!$K:$M, 3) ), B5=55, IF(Z4 >= AD5, Z4 - AD5, 0), B5>55, 0 ) -> 3939.448 | AA5: =IFS( B5<65, IF(AA4+J5 < VLOOKUP(YEAR(A5), Lookup!$Q:$R, 2), AA4 + IF(MONTH(A5)=12, R4+X4, 0) + J5, MIN( AA4 + IF(MONTH(A5)=12, R4+X4, 0) + J5 , VLOOKUP(YEAR(A5), Lookup!$Q:$R, 2) ) ), B5>=65, IF(AA4+J5 < VLOOKUP(questions!$C$5, Lookup!$Q:$R, 2), AA4 + IF(MONTH(A5)=12, R4+X4, 0) + J5 , MIN( AA4 + IF(MONTH(A5)=12, R4+X4, 0) + J5, VLOOKUP(questions!$C$5, Lookup!$Q:$R, 2) ) ) ) -> 4419.856 | AB5: =IFS( B5<55, 0, B5=55, MIN(Y4+Z4, AD5), B5>55, IF(AB4 < $AH$7, MIN(AB4 + IF(MONTH(A5)=12, Q5+W5, 0) + K5, $AH$7), AB4 + IF(MONTH(A5)=12, Q5+W5, 0) + K5 ) ) -> 0 | AC5: {=IFS(B5<66, XLOOKUP(year(A5),Lookup!$K$13:$K1000,Lookup!$L$13:$L1000,"missing",,1),B5>65,XLOOKUP(questions!$C$5,Lookup!$K$13:$K1000,Lookup!$L$13:$L1000,"missing",,1))} -> 110200 | AD5: {=IFS(B5<66, XLOOKUP(year(A5),Lookup!$K$13:$K1000,Lookup!$M$13:$M1000,"missing",,1),B5>65, XLOOKUP(questions!$C$5,Lookup!$K$13:$K1000,Lookup!$M$13:$M1000,"missing",,1))} -> 220400 | AE5: {=IFS(B5<66, XLOOKUP(year(A5),Lookup!$K$13:$K1000,Lookup!$N$13:$N1000,"missing",,1),B5>65,XLOOKUP(questions!$C$5,Lookup!$K$13:$K1000,Lookup!$N$13:$N1000,"missing",,1))} -> 440800 | AG5: Ordinary Account (OA) | AH5: Special Account (SA) | AI5: Medisave Account (MA) | AJ5: Total
A6: =eomonth(EDATE(A5,1),0) -> 46203 | B6: =round(YEARFRAC(EOMONTH(questions!$C$3, 0),A6,1),2) -> 27.58 | C6: =IF(B6<questions!$C$6,if(MONTH(A6)=1,C5*(1+questions!$C$12),C5),0) -> 10000 | D6: =IF(MONTH(A6)=12,C6*questions!$C$11,0) -> 0 | E6: =MIN(C6,IF(YEAR(A6)=2025,7600,8000)) -> 8000 | F6: =MIN(102000-E6*12,D6) -> 0 | G6: {=if(YEAR(A6)=2025,XLOOKUP(B6,Lookup!$A$3:$A$7,Lookup!$D$3:$D$7,,1)*SUM(E6:F6), XLOOKUP(B6,Lookup!$A$14:$A$18,Lookup!$D$14:$D$18,,1)*SUM(E6:F6))} -> 2960 | H6: {=if(YEAR(A6)=2025,XLOOKUP(B6,Lookup!$F$3:$F$10,Lookup!$G$3:$G$10,,1)*G6, XLOOKUP(B6,Lookup!$F$14:$F$21,Lookup!$G$14:$G$21,,1)*G6)} -> 1840.232 | I6: {=if(B6<55, if(YEAR(A6)=2025,XLOOKUP(B6,Lookup!$F$3:$F$10,Lookup!$H$3:$H$10,,1)*G6, XLOOKUP(B6,Lookup!$F$14:$F$21,Lookup!$H$14:$H$21,,1)*G6),0)} -> 479.816 | J6: {=if(YEAR(A6)=2025,XLOOKUP(B6,Lookup!$F$3:$F$10,Lookup!$I$3:$I$10,,1)*G6, XLOOKUP(B6,Lookup!$F$14:$F$21,Lookup!$I$14:$I$21,,1)*G6)} -> 639.952 | K6: {=if(B6>54, if(YEAR(A6)=2025,XLOOKUP(B6,Lookup!$F$3:$F$10,Lookup!$H$3:$H$10,,1)*G6, XLOOKUP(B6,Lookup!$F$14:$F$21,Lookup!$H$14:$H$21,,1)*G6),0)} -> 0 | L6: =IF(and(A6<questions!$C$19,questions!$C$18="yes"),questions!$C$20,0) -> 700 | M6: =(Y5+H6)*Lookup!A$26/12 -> 26.585267 | N6: =if(B6<55, (Z5+I6)*Lookup!B$26/12, (AB5+K6)*Lookup!B$26/12) -> 14.73088 | O6: =(AA5+J6)*Lookup!C$26/12 -> 16.866027 | P6: =IF(year(A6)=year(A5), P5+M6, M6) -> 92.088167 | Q6: =IF(year(A6)=year(A5), Q5+N6, N6) -> 49.3272 | R6: =IF(year(A6)=year(A5), R5+O6, O6) -> 54.665067 | S6: =if(B6<55,min(20000,Y5)*0.01/12,min(20000,Y5)*0.02/12) -> 9.10058 | T6: =if(B6<=55,min(60000-min(20000,Y5),Z5)*0.01/12,min(30000-min(20000,Y5),AB5)*0.02/12+min(30000,AB5)*0.01/12) -> 3.2828733 | U6: =if(B6<55,min(60000-min(60000-min(20000,Y5),Z5)-min(20000,Y5),AA5)*0.01/12,min(30000-min(30000-min(20000,Y5),AB5)-min(20000,Y5),AA5)*0.02/12+min(30000-min(30000-min(20000,Y5),AB5)-min(20000,Y5),AA5)*0.01/12) -> 3.6832133 | V6: =IF(year($A6)=year($A5), V5+S6, S6) -> 30.70116 | W6: =IF(year($A6)=year($A5), W5+T6, T6) -> 10.732413 | X6: =IF(year($A6)=year($A5), X5+U6, U6) -> 11.533093 | Y6: =IFS( B6<55, MAX( Y5 + IF(MONTH(A6)=12, P6+V6, 0) + H6 - L6 + MAX(0, IF(AA5 >= VLOOKUP(YEAR(A6), Lookup!$Q:$R, 2), Z5 + IF(MONTH(A6)=12, Q6+W6, 0) + I6 + AA5 + IF(MONTH(A6)=12, R6+X6, 0) - VLOOKUP(YEAR(A6), Lookup!$Q:$R, 2) + J6, Z5 + IF(MONTH(A6)=12, Q6+W6, 0) + I6 ) - VLOOKUP(YEAR(A6), Lookup!$K:$M, 3) ), 0), B6=55, IF(Z5>=AD6, MAX(Y5 + IF(MONTH(A6)=12, P6+V6, 0) + H6 - L6, 0), MAX(MAX(0, Y5-(AD6-Z5)) + IF(MONTH(A6)=12, P6+V6, 0) + H6 - L6, 0) ), B6>55, IF(AB5>=$AH$7, MAX(Y5 + IF(MONTH(A6)=12, P6+V6, 0) + H6 - L6 + K6 + Z5, 0), MAX(Y5 + IF(MONTH(A6)=12, P6+V6, 0) + H6 - L6, 0) ) ) -> 12060.928 | Z6: =IFS( B6<55, MIN( IF(AA5 >= VLOOKUP(YEAR(A6), Lookup!$Q:$R, 2), Z5 + IF(MONTH(A6)=12, Q6+W6, 0) + I6 + AA5 + IF(MONTH(A6)=12, R6+X6, 0) - VLOOKUP(YEAR(A6), Lookup!$Q:$R, 2) + J6, Z5 + IF(MONTH(A6)=12, Q6+W6, 0) + I6 ), VLOOKUP(YEAR(A6), Lookup!$K:$M, 3) ), B6=55, IF(Z5 >= AD6, Z5 - AD6, 0), B6>55, 0 ) -> 4419.264 | AA6: =IFS( B6<65, IF(AA5+J6 < VLOOKUP(YEAR(A6), Lookup!$Q:$R, 2), AA5 + IF(MONTH(A6)=12, R5+X5, 0) + J6, MIN( AA5 + IF(MONTH(A6)=12, R5+X5, 0) + J6 , VLOOKUP(YEAR(A6), Lookup!$Q:$R, 2) ) ), B6>=65, IF(AA5+J6 < VLOOKUP(questions!$C$5, Lookup!$Q:$R, 2), AA5 + IF(MONTH(A6)=12, R5+X5, 0) + J6 , MIN( AA5 + IF(MONTH(A6)=12, R5+X5, 0) + J6, VLOOKUP(questions!$C$5, Lookup!$Q:$R, 2) ) ) ) -> 5059.808 | AB6: =IFS( B6<55, 0, B6=55, MIN(Y5+Z5, AD6), B6>55, IF(AB5 < $AH$7, MIN(AB5 + IF(MONTH(A6)=12, Q6+W6, 0) + K6, $AH$7), AB5 + IF(MONTH(A6)=12, Q6+W6, 0) + K6 ) ) -> 0 | AC6: {=IFS(B6<66, XLOOKUP(year(A6),Lookup!$K$13:$K1000,Lookup!$L$13:$L1000,"missing",,1),B6>65,XLOOKUP(questions!$C$5,Lookup!$K$13:$K1000,Lookup!$L$13:$L1000,"missing",,1))} -> 110200 | AD6: {=IFS(B6<66, XLOOKUP(year(A6),Lookup!$K$13:$K1000,Lookup!$M$13:$M1000,"missing",,1),B6>65, XLOOKUP(questions!$C$5,Lookup!$K$13:$K1000,Lookup!$M$13:$M1000,"missing",,1))} -> 220400 | AE6: {=IFS(B6<66, XLOOKUP(year(A6),Lookup!$K$13:$K1000,Lookup!$N$13:$N1000,"missing",,1),B6>65,XLOOKUP(questions!$C$5,Lookup!$K$13:$K1000,Lookup!$N$13:$N1000,"missing",,1))} -> 440800
A7: =eomonth(EDATE(A6,1),0) -> 46234 | B7: =round(YEARFRAC(EOMONTH(questions!$C$3, 0),A7,1),2) -> 27.67 | C7: =IF(B7<questions!$C$6,if(MONTH(A7)=1,C6*(1+questions!$C$12),C6),0) -> 10000 | D7: =IF(MONTH(A7)=12,C7*questions!$C$11,0) -> 0 | E7: =MIN(C7,IF(YEAR(A7)=2025,7600,8000)) -> 8000 | F7: =MIN(102000-E7*12,D7) -> 0 | G7: {=if(YEAR(A7)=2025,XLOOKUP(B7,Lookup!$A$3:$A$7,Lookup!$D$3:$D$7,,1)*SUM(E7:F7), XLOOKUP(B7,Lookup!$A$14:$A$18,Lookup!$D$14:$D$18,,1)*SUM(E7:F7))} -> 2960 | H7: {=if(YEAR(A7)=2025,XLOOKUP(B7,Lookup!$F$3:$F$10,Lookup!$G$3:$G$10,,1)*G7, XLOOKUP(B7,Lookup!$F$14:$F$21,Lookup!$G$14:$G$21,,1)*G7)} -> 1840.232 | I7: {=if(B7<55, if(YEAR(A7)=2025,XLOOKUP(B7,Lookup!$F$3:$F$10,Lookup!$H$3:$H$10,,1)*G7, XLOOKUP(B7,Lookup!$F$14:$F$21,Lookup!$H$14:$H$21,,1)*G7),0)} -> 479.816 | J7: {=if(YEAR(A7)=2025,XLOOKUP(B7,Lookup!$F$3:$F$10,Lookup!$I$3:$I$10,,1)*G7, XLOOKUP(B7,Lookup!$F$14:$F$21,Lookup!$I$14:$I$21,,1)*G7)} -> 639.952 | K7: {=if(B7>54, if(YEAR(A7)=2025,XLOOKUP(B7,Lookup!$F$3:$F$10,Lookup!$H$3:$H$10,,1)*G7, XLOOKUP(B7,Lookup!$F$14:$F$21,Lookup!$H$14:$H$21,,1)*G7),0)} -> 0 | L7: =IF(and(A7<questions!$C$19,questions!$C$18="yes"),questions!$C$20,0) -> 700 | M7: =(Y6+H7)*Lookup!A$26/12 -> 28.96075 | N7: =if(B7<55, (Z6+I7)*Lookup!B$26/12, (AB6+K7)*Lookup!B$26/12) -> 16.330267 | O7: =(AA6+J7)*Lookup!C$26/12 -> 18.9992 | P7: =IF(year(A7)=year(A6), P6+M7, M7) -> 121.04892 | Q7: =IF(year(A7)=year(A6), Q6+N7, N7) -> 65.657467 | R7: =IF(year(A7)=year(A6), R6+O7, O7) -> 73.664267 | S7: =if(B7<55,min(20000,Y6)*0.01/12,min(20000,Y6)*0.02/12) -> 10.050773 | T7: =if(B7<=55,min(60000-min(20000,Y6),Z6)*0.01/12,min(30000-min(20000,Y6),AB6)*0.02/12+min(30000,AB6)*0.01/12) -> 3.68272 | U7: =if(B7<55,min(60000-min(60000-min(20000,Y6),Z6)-min(20000,Y6),AA6)*0.01/12,min(30000-min(30000-min(20000,Y6),AB6)-min(20000,Y6),AA6)*0.02/12+min(30000-min(30000-min(20000,Y6),AB6)-min(20000,Y6),AA6)*0.01/12) -> 4.2165067 | V7: =IF(year($A7)=year($A6), V6+S7, S7) -> 40.751933 | W7: =IF(year($A7)=year($A6), W6+T7, T7) -> 14.415133 | X7: =IF(year($A7)=year($A6), X6+U7, U7) -> 15.7496 | Y7: =IFS( B7<55, MAX( Y6 + IF(MONTH(A7)=12, P7+V7, 0) + H7 - L7 + MAX(0, IF(AA6 >= VLOOKUP(YEAR(A7), Lookup!$Q:$R, 2), Z6 + IF(MONTH(A7)=12, Q7+W7, 0) + I7 + AA6 + IF(MONTH(A7)=12, R7+X7, 0) - VLOOKUP(YEAR(A7), Lookup!$Q:$R, 2) + J7, Z6 + IF(MONTH(A7)=12, Q7+W7, 0) + I7 ) - VLOOKUP(YEAR(A7), Lookup!$K:$M, 3) ), 0), B7=55, IF(Z6>=AD7, MAX(Y6 + IF(MONTH(A7)=12, P7+V7, 0) + H7 - L7, 0), MAX(MAX(0, Y6-(AD7-Z6)) + IF(MONTH(A7)=12, P7+V7, 0) + H7 - L7, 0) ), B7>55, IF(AB6>=$AH$7, MAX(Y6 + IF(MONTH(A7)=12, P7+V7, 0) + H7 - L7 + K7 + Z6, 0), MAX(Y6 + IF(MONTH(A7)=12, P7+V7, 0) + H7 - L7, 0) ) ) -> 13201.16 | Z7: =IFS( B7<55, MIN( IF(AA6 >= VLOOKUP(YEAR(A7), Lookup!$Q:$R, 2), Z6 + IF(MONTH(A7)=12, Q7+W7, 0) + I7 + AA6 + IF(MONTH(A7)=12, R7+X7, 0) - VLOOKUP(YEAR(A7), Lookup!$Q:$R, 2) + J7, Z6 + IF(MONTH(A7)=12, Q7+W7, 0) + I7 ), VLOOKUP(YEAR(A7), Lookup!$K:$M, 3) ), B7=55, IF(Z6 >= AD7, Z6 - AD7, 0), B7>55, 0 ) -> 4899.08 | AA7: =IFS( B7<65, IF(AA6+J7 < VLOOKUP(YEAR(A7), Lookup!$Q:$R, 2), AA6 + IF(MONTH(A7)=12, R6+X6, 0) + J7, MIN( AA6 + IF(MONTH(A7)=12, R6+X6, 0) + J7 , VLOOKUP(YEAR(A7), Lookup!$Q:$R, 2) ) ), B7>=65, IF(AA6+J7 < VLOOKUP(questions!$C$5, Lookup!$Q:$R, 2), AA6 + IF(MONTH(A7)=12, R6+X6, 0) + J7 , MIN( AA6 + IF(MONTH(A7)=12, R6+X6, 0) + J7, VLOOKUP(questions!$C$5, Lookup!$Q:$R, 2) ) ) ) -> 5699.76 | AB7: =IFS( B7<55, 0, B7=55, MIN(Y6+Z6, AD7), B7>55, IF(AB6 < $AH$7, MIN(AB6 + IF(MONTH(A7)=12, Q7+W7, 0) + K7, $AH$7), AB6 + IF(MONTH(A7)=12, Q7+W7, 0) + K7 ) ) -> 0 | AC7: {=IFS(B7<66, XLOOKUP(year(A7),Lookup!$K$13:$K1000,Lookup!$L$13:$L1000,"missing",,1),B7>65,XLOOKUP(questions!$C$5,Lookup!$K$13:$K1000,Lookup!$L$13:$L1000,"missing",,1))} -> 110200 | AD7: {=IFS(B7<66, XLOOKUP(year(A7),Lookup!$K$13:$K1000,Lookup!$M$13:$M1000,"missing",,1),B7>65, XLOOKUP(questions!$C$5,Lookup!$K$13:$K1000,Lookup!$M$13:$M1000,"missing",,1))} -> 220400 | AE7: {=IFS(B7<66, XLOOKUP(year(A7),Lookup!$K$13:$K1000,Lookup!$N$13:$N1000,"missing",,1),B7>65,XLOOKUP(questions!$C$5,Lookup!$K$13:$K1000,Lookup!$N$13:$N1000,"missing",,1))} -> 440800 | AG7: {=XLOOKUP(questions!C4,Lookup!$K$3:$K1000,Lookup!$L$3:$L1000,"missing",,1)} -> 279083.87 | AH7: {=XLOOKUP(questions!C4,Lookup!$K$3:$K1000,Lookup!$M$3:$M1000,"missing",,1)} -> 558167.74 | AI7: {=XLOOKUP(questions!C4,Lookup!$K$3:$K1000,Lookup!$N$3:$N1000,"missing",,1)} -> 1116335.5
A8: =eomonth(EDATE(A7,1),0) -> 46265 | B8: =round(YEARFRAC(EOMONTH(questions!$C$3, 0),A8,1),2) -> 27.75 | C8: =IF(B8<questions!$C$6,if(MONTH(A8)=1,C7*(1+questions!$C$12),C7),0) -> 10000 | D8: =IF(MONTH(A8)=12,C8*questions!$C$11,0) -> 0 | E8: =MIN(C8,IF(YEAR(A8)=2025,7600,8000)) -> 8000 | F8: =MIN(102000-E8*12,D8) -> 0 | G8: {=if(YEAR(A8)=2025,XLOOKUP(B8,Lookup!$A$3:$A$7,Lookup!$D$3:$D$7,,1)*SUM(E8:F8), XLOOKUP(B8,Lookup!$A$14:$A$18,Lookup!$D$14:$D$18,,1)*SUM(E8:F8))} -> 2960 | H8: {=if(YEAR(A8)=2025,XLOOKUP(B8,Lookup!$F$3:$F$10,Lookup!$G$3:$G$10,,1)*G8, XLOOKUP(B8,Lookup!$F$14:$F$21,Lookup!$G$14:$G$21,,1)*G8)} -> 1840.232 | I8: {=if(B8<55, if(YEAR(A8)=2025,XLOOKUP(B8,Lookup!$F$3:$F$10,Lookup!$H$3:$H$10,,1)*G8, XLOOKUP(B8,Lookup!$F$14:$F$21,Lookup!$H$14:$H$21,,1)*G8),0)} -> 479.816 | J8: {=if(YEAR(A8)=2025,XLOOKUP(B8,Lookup!$F$3:$F$10,Lookup!$I$3:$I$10,,1)*G8, XLOOKUP(B8,Lookup!$F$14:$F$21,Lookup!$I$14:$I$21,,1)*G8)} -> 639.952 | K8: {=if(B8>54, if(YEAR(A8)=2025,XLOOKUP(B8,Lookup!$F$3:$F$10,Lookup!$H$3:$H$10,,1)*G8, XLOOKUP(B8,Lookup!$F$14:$F$21,Lookup!$H$14:$H$21,,1)*G8),0)} -> 0 | L8: =IF(and(A8<questions!$C$19,questions!$C$18="yes"),questions!$C$20,0) -> 700 | M8: =(Y7+H8)*Lookup!A$26/12 -> 31.336233 | N8: =if(B8<55, (Z7+I8)*Lookup!B$26/12, (AB7+K8)*Lookup!B$26/12) -> 17.929653 | O8: =(AA7+J8)*Lookup!C$26/12 -> 21.132373 | P8: =IF(year(A8)=year(A7), P7+M8, M8) -> 152.38515 | Q8: =IF(year(A8)=year(A7), Q7+N8, N8) -> 83.58712 | R8: =IF(year(A8)=year(A7), R7+O8, O8) -> 94.79664 | S8: =if(B8<55,min(20000,Y7)*0.01/12,min(20000,Y7)*0.02/12) -> 11.000967 | T8: =if(B8<=55,min(60000-min(20000,Y7),Z7)*0.01/12,min(30000-min(20000,Y7),AB7)*0.02/12+min(30000,AB7)*0.01/12) -> 4.0825667 | U8: =if(B8<55,min(60000-min(60000-min(20000,Y7),Z7)-min(20000,Y7),AA7)*0.01/12,min(30000-min(30000-min(20000,Y7),AB7)-min(20000,Y7),AA7)*0.02/12+min(30000-min(30000-min(20000,Y7),AB7)-min(20000,Y7),AA7)*0.01/12) -> 4.7498 | V8: =IF(year($A8)=year($A7), V7+S8, S8) -> 51.7529 | W8: =IF(year($A8)=year($A7), W7+T8, T8) -> 18.4977 | X8: =IF(year($A8)=year($A7), X7+U8, U8) -> 20.4994 | Y8: =IFS( B8<55, MAX( Y7 + IF(MONTH(A8)=12, P8+V8, 0) + H8 - L8 + MAX(0, IF(AA7 >= VLOOKUP(YEAR(A8), Lookup!$Q:$R, 2), Z7 + IF(MONTH(A8)=12, Q8+W8, 0) + I8 + AA7 + IF(MONTH(A8)=12, R8+X8, 0) - VLOOKUP(YEAR(A8), Lookup!$Q:$R, 2) + J8, Z7 + IF(MONTH(A8)=12, Q8+W8, 0) + I8 ) - VLOOKUP(YEAR(A8), Lookup!$K:$M, 3) ), 0), B8=55, IF(Z7>=AD8, MAX(Y7 + IF(MONTH(A8)=12, P8+V8, 0) + H8 - L8, 0), MAX(MAX(0, Y7-(AD8-Z7)) + IF(MONTH(A8)=12, P8+V8, 0) + H8 - L8, 0) ), B8>55, IF(AB7>=$AH$7, MAX(Y7 + IF(MONTH(A8)=12, P8+V8, 0) + H8 - L8 + K8 + Z7, 0), MAX(Y7 + IF(MONTH(A8)=12, P8+V8, 0) + H8 - L8, 0) ) ) -> 14341.392 | Z8: =IFS( B8<55, MIN( IF(AA7 >= VLOOKUP(YEAR(A8), Lookup!$Q:$R, 2), Z7 + IF(MONTH(A8)=12, Q8+W8, 0) + I8 + AA7 + IF(MONTH(A8)=12, R8+X8, 0) - VLOOKUP(YEAR(A8), Lookup!$Q:$R, 2) + J8, Z7 + IF(MONTH(A8)=12, Q8+W8, 0) + I8 ), VLOOKUP(YEAR(A8), Lookup!$K:$M, 3) ), B8=55, IF(Z7 >= AD8, Z7 - AD8, 0), B8>55, 0 ) -> 5378.896 | AA8: =IFS( B8<65, IF(AA7+J8 < VLOOKUP(YEAR(A8), Lookup!$Q:$R, 2), AA7 + IF(MONTH(A8)=12, R7+X7, 0) + J8, MIN( AA7 + IF(MONTH(A8)=12, R7+X7, 0) + J8 , VLOOKUP(YEAR(A8), Lookup!$Q:$R, 2) ) ), B8>=65, IF(AA7+J8 < VLOOKUP(questions!$C$5, Lookup!$Q:$R, 2), AA7 + IF(MONTH(A8)=12, R7+X7, 0) + J8 , MIN( AA7 + IF(MONTH(A8)=12, R7+X7, 0) + J8, VLOOKUP(questions!$C$5, Lookup!$Q:$R, 2) ) ) ) -> 6339.712 | AB8: =IFS( B8<55, 0, B8=55, MIN(Y7+Z7, AD8), B8>55, IF(AB7 < $AH$7, MIN(AB7 + IF(MONTH(A8)=12, Q8+W8, 0) + K8, $AH$7), AB7 + IF(MONTH(A8)=12, Q8+W8, 0) + K8 ) ) -> 0 | AC8: {=IFS(B8<66, XLOOKUP(year(A8),Lookup!$K$13:$K1000,Lookup!$L$13:$L1000,"missing",,1),B8>65,XLOOKUP(questions!$C$5,Lookup!$K$13:$K1000,Lookup!$L$13:$L1000,"missing",,1))} -> 110200 | AD8: {=IFS(B8<66, XLOOKUP(year(A8),Lookup!$K$13:$K1000,Lookup!$M$13:$M1000,"missing",,1),B8>65, XLOOKUP(questions!$C$5,Lookup!$K$13:$K1000,Lookup!$M$13:$M1000,"missing",,1))} -> 220400 | AE8: {=IFS(B8<66, XLOOKUP(year(A8),Lookup!$K$13:$K1000,Lookup!$N$13:$N1000,"missing",,1),B8>65,XLOOKUP(questions!$C$5,Lookup!$K$13:$K1000,Lookup!$N$13:$N1000,"missing",,1))} -> 440800 | AG8: Basic Retirement Sum (BRS) | AH8: Full Retirement Sum (FRS) | AI8: Enhanced Retirement Sum (ERS)
A9: =eomonth(EDATE(A8,1),0) -> 46295 | B9: =round(YEARFRAC(EOMONTH(questions!$C$3, 0),A9,1),2) -> 27.83 | C9: =IF(B9<questions!$C$6,if(MONTH(A9)=1,C8*(1+questions!$C$12),C8),0) -> 10000 | D9: =IF(MONTH(A9)=12,C9*questions!$C$11,0) -> 0 | E9: =MIN(C9,IF(YEAR(A9)=2025,7600,8000)) -> 8000 | F9: =MIN(102000-E9*12,D9) -> 0 | G9: {=if(YEAR(A9)=2025,XLOOKUP(B9,Lookup!$A$3:$A$7,Lookup!$D$3:$D$7,,1)*SUM(E9:F9), XLOOKUP(B9,Lookup!$A$14:$A$18,Lookup!$D$14:$D$18,,1)*SUM(E9:F9))} -> 2960 | H9: {=if(YEAR(A9)=2025,XLOOKUP(B9,Lookup!$F$3:$F$10,Lookup!$G$3:$G$10,,1)*G9, XLOOKUP(B9,Lookup!$F$14:$F$21,Lookup!$G$14:$G$21,,1)*G9)} -> 1840.232 | I9: {=if(B9<55, if(YEAR(A9)=2025,XLOOKUP(B9,Lookup!$F$3:$F$10,Lookup!$H$3:$H$10,,1)*G9, XLOOKUP(B9,Lookup!$F$14:$F$21,Lookup!$H$14:$H$21,,1)*G9),0)} -> 479.816 | J9: {=if(YEAR(A9)=2025,XLOOKUP(B9,Lookup!$F$3:$F$10,Lookup!$I$3:$I$10,,1)*G9, XLOOKUP(B9,Lookup!$F$14:$F$21,Lookup!$I$14:$I$21,,1)*G9)} -> 639.952 | K9: {=if(B9>54, if(YEAR(A9)=2025,XLOOKUP(B9,Lookup!$F$3:$F$10,Lookup!$H$3:$H$10,,1)*G9, XLOOKUP(B9,Lookup!$F$14:$F$21,Lookup!$H$14:$H$21,,1)*G9),0)} -> 0 | L9: =IF(and(A9<questions!$C$19,questions!$C$18="yes"),questions!$C$20,0) -> 700 | M9: =(Y8+H9)*Lookup!A$26/12 -> 33.711717 | N9: =if(B9<55, (Z8+I9)*Lookup!B$26/12, (AB8+K9)*Lookup!B$26/12) -> 19.52904 | O9: =(AA8+J9)*Lookup!C$26/12 -> 23.265547 | P9: =IF(year(A9)=year(A8), P8+M9, M9) -> 186.09687 | Q9: =IF(year(A9)=year(A8), Q8+N9, N9) -> 103.11616 | R9: =IF(year(A9)=year(A8), R8+O9, O9) -> 118.06219 | S9: =if(B9<55,min(20000,Y8)*0.01/12,min(20000,Y8)*0.02/12) -> 11.95116 | T9: =if(B9<=55,min(60000-min(20000,Y8),Z8)*0.01/12,min(30000-min(20000,Y8),AB8)*0.02/12+min(30000,AB8)*0.01/12) -> 4.4824133 | U9: =if(B9<55,min(60000-min(60000-min(20000,Y8),Z8)-min(20000,Y8),AA8)*0.01/12,min(30000-min(30000-min(20000,Y8),AB8)-min(20000,Y8),AA8)*0.02/12+min(30000-min(30000-min(20000,Y8),AB8)-min(20000,Y8),AA8)*0.01/12) -> 5.2830933 | V9: =IF(year($A9)=year($A8), V8+S9, S9) -> 63.70406 | W9: =IF(year($A9)=year($A8), W8+T9, T9) -> 22.980113 | X9: =IF(year($A9)=year($A8), X8+U9, U9) -> 25.782493 | Y9: =IFS( B9<55, MAX( Y8 + IF(MONTH(A9)=12, P9+V9, 0) + H9 - L9 + MAX(0, IF(AA8 >= VLOOKUP(YEAR(A9), Lookup!$Q:$R, 2), Z8 + IF(MONTH(A9)=12, Q9+W9, 0) + I9 + AA8 + IF(MONTH(A9)=12, R9+X9, 0) - VLOOKUP(YEAR(A9), Lookup!$Q:$R, 2) + J9, Z8 + IF(MONTH(A9)=12, Q9+W9, 0) + I9 ) - VLOOKUP(YEAR(A9), Lookup!$K:$M, 3) ), 0), B9=55, IF(Z8>=AD9, MAX(Y8 + IF(MONTH(A9)=12, P9+V9, 0) + H9 - L9, 0), MAX(MAX(0, Y8-(AD9-Z8)) + IF(MONTH(A9)=12, P9+V9, 0) + H9 - L9, 0) ), B9>55, IF(AB8>=$AH$7, MAX(Y8 + IF(MONTH(A9)=12, P9+V9, 0) + H9 - L9 + K9 + Z8, 0), MAX(Y8 + IF(MONTH(A9)=12, P9+V9, 0) + H9 - L9, 0) ) ) -> 15481.624 | Z9: =IFS( B9<55, MIN( IF(AA8 >= VLOOKUP(YEAR(A9), Lookup!$Q:$R, 2), Z8 + IF(MONTH(A9)=12, Q9+W9, 0) + I9 + AA8 + IF(MONTH(A9)=12, R9+X9, 0) - VLOOKUP(YEAR(A9), Lookup!$Q:$R, 2) + J9, Z8 + IF(MONTH(A9)=12, Q9+W9, 0) + I9 ), VLOOKUP(YEAR(A9), Lookup!$K:$M, 3) ), B9=55, IF(Z8 >= AD9, Z8 - AD9, 0), B9>55, 0 ) -> 5858.712 | AA9: =IFS( B9<65, IF(AA8+J9 < VLOOKUP(YEAR(A9), Lookup!$Q:$R, 2), AA8 + IF(MONTH(A9)=12, R8+X8, 0) + J9, MIN( AA8 + IF(MONTH(A9)=12, R8+X8, 0) + J9 , VLOOKUP(YEAR(A9), Lookup!$Q:$R, 2) ) ), B9>=65, IF(AA8+J9 < VLOOKUP(questions!$C$5, Lookup!$Q:$R, 2), AA8 + IF(MONTH(A9)=12, R8+X8, 0) + J9 , MIN( AA8 + IF(MONTH(A9)=12, R8+X8, 0) + J9, VLOOKUP(questions!$C$5, Lookup!$Q:$R, 2) ) ) ) -> 6979.664 | AB9: =IFS( B9<55, 0, B9=55, MIN(Y8+Z8, AD9), B9>55, IF(AB8 < $AH$7, MIN(AB8 + IF(MONTH(A9)=12, Q9+W9, 0) + K9, $AH$7), AB8 + IF(MONTH(A9)=12, Q9+W9, 0) + K9 ) ) -> 0 | AC9: {=IFS(B9<66, XLOOKUP(year(A9),Lookup!$K$13:$K1000,Lookup!$L$13:$L1000,"missing",,1),B9>65,XLOOKUP(questions!$C$5,Lookup!$K$13:$K1000,Lookup!$L$13:$L1000,"missing",,1))} -> 110200 | AD9: {=IFS(B9<66, XLOOKUP(year(A9),Lookup!$K$13:$K1000,Lookup!$M$13:$M1000,"missing",,1),B9>65, XLOOKUP(questions!$C$5,Lookup!$K$13:$K1000,Lookup!$M$13:$M1000,"missing",,1))} -> 220400 | AE9: {=IFS(B9<66, XLOOKUP(year(A9),Lookup!$K$13:$K1000,Lookup!$N$13:$N1000,"missing",,1),B9>65,XLOOKUP(questions!$C$5,Lookup!$K$13:$K1000,Lookup!$N$13:$N1000,"missing",,1))} -> 440800
A10: =eomonth(EDATE(A9,1),0) -> 46326 | B10: =round(YEARFRAC(EOMONTH(questions!$C$3, 0),A10,1),2) -> 27.92 | C10: =IF(B10<questions!$C$6,if(MONTH(A10)=1,C9*(1+questions!$C$12),C9),0) -> 10000 | D10: =IF(MONTH(A10)=12,C10*questions!$C$11,0) -> 0 | E10: =MIN(C10,IF(YEAR(A10)=2025,7600,8000)) -> 8000 | F10: =MIN(102000-E10*12,D10) -> 0 | G10: {=if(YEAR(A10)=2025,XLOOKUP(B10,Lookup!$A$3:$A$7,Lookup!$D$3:$D$7,,1)*SUM(E10:F10), XLOOKUP(B10,Lookup!$A$14:$A$18,Lookup!$D$14:$D$18,,1)*SUM(E10:F10))} -> 2960 | H10: {=if(YEAR(A10)=2025,XLOOKUP(B10,Lookup!$F$3:$F$10,Lookup!$G$3:$G$10,,1)*G10, XLOOKUP(B10,Lookup!$F$14:$F$21,Lookup!$G$14:$G$21,,1)*G10)} -> 1840.232 | I10: {=if(B10<55, if(YEAR(A10)=2025,XLOOKUP(B10,Lookup!$F$3:$F$10,Lookup!$H$3:$H$10,,1)*G10, XLOOKUP(B10,Lookup!$F$14:$F$21,Lookup!$H$14:$H$21,,1)*G10),0)} -> 479.816 | J10: {=if(YEAR(A10)=2025,XLOOKUP(B10,Lookup!$F$3:$F$10,Lookup!$I$3:$I$10,,1)*G10, XLOOKUP(B10,Lookup!$F$14:$F$21,Lookup!$I$14:$I$21,,1)*G10)} -> 639.952 | K10: {=if(B10>54, if(YEAR(A10)=2025,XLOOKUP(B10,Lookup!$F$3:$F$10,Lookup!$H$3:$H$10,,1)*G10, XLOOKUP(B10,Lookup!$F$14:$F$21,Lookup!$H$14:$H$21,,1)*G10),0)} -> 0 | L10: =IF(and(A10<questions!$C$19,questions!$C$18="yes"),questions!$C$20,0) -> 700 | M10: =(Y9+H10)*Lookup!A$26/12 -> 36.0872 | N10: =if(B10<55, (Z9+I10)*Lookup!B$26/12, (AB9+K10)*Lookup!B$26/12) -> 21.128427 | O10: =(AA9+J10)*Lookup!C$26/12 -> 25.39872 | P10: =IF(year(A10)=year(A9), P9+M10, M10) -> 222.18407 | Q10: =IF(year(A10)=year(A9), Q9+N10, N10) -> 124.24459 | R10: =IF(year(A10)=year(A9), R9+O10, O10) -> 143.46091 | S10: =if(B10<55,min(20000,Y9)*0.01/12,min(20000,Y9)*0.02/12) -> 12.901353 | T10: =if(B10<=55,min(60000-min(20000,Y9),Z9)*0.01/12,min(30000-min(20000,Y9),AB9)*0.02/12+min(30000,AB9)*0.01/12) -> 4.88226 | U10: =if(B10<55,min(60000-min(60000-min(20000,Y9),Z9)-min(20000,Y9),AA9)*0.01/12,min(30000-min(30000-min(20000,Y9),AB9)-min(20000,Y9),AA9)*0.02/12+min(30000-min(30000-min(20000,Y9),AB9)-min(20000,Y9),AA9)*0.01/12) -> 5.8163867 | V10: =IF(year($A10)=year($A9), V9+S10, S10) -> 76.605413 | W10: =IF(year($A10)=year($A9), W9+T10, T10) -> 27.862373 | X10: =IF(year($A10)=year($A9), X9+U10, U10) -> 31.59888 | Y10: =IFS( B10<55, MAX( Y9 + IF(MONTH(A10)=12, P10+V10, 0) + H10 - L10 + MAX(0, IF(AA9 >= VLOOKUP(YEAR(A10), Lookup!$Q:$R, 2), Z9 + IF(MONTH(A10)=12, Q10+W10, 0) + I10 + AA9 + IF(MONTH(A10)=12, R10+X10, 0) - VLOOKUP(YEAR(A10), Lookup!$Q:$R, 2) + J10, Z9 + IF(MONTH(A10)=12, Q10+W10, 0) + I10 ) - VLOOKUP(YEAR(A10), Lookup!$K:$M, 3) ), 0), B10=55, IF(Z9>=AD10, MAX(Y9 + IF(MONTH(A10)=12, P10+V10, 0) + H10 - L10, 0), MAX(MAX(0, Y9-(AD10-Z9)) + IF(MONTH(A10)=12, P10+V10, 0) + H10 - L10, 0) ), B10>55, IF(AB9>=$AH$7, MAX(Y9 + IF(MONTH(A10)=12, P10+V10, 0) + H10 - L10 + K10 + Z9, 0), MAX(Y9 + IF(MONTH(A10)=12, P10+V10, 0) + H10 - L10, 0) ) ) -> 16621.856 | Z10: =IFS( B10<55, MIN( IF(AA9 >= VLOOKUP(YEAR(A10), Lookup!$Q:$R, 2), Z9 + IF(MONTH(A10)=12, Q10+W10, 0) + I10 + AA9 + IF(MONTH(A10)=12, R10+X10, 0) - VLOOKUP(YEAR(A10), Lookup!$Q:$R, 2) + J10, Z9 + IF(MONTH(A10)=12, Q10+W10, 0) + I10 ), VLOOKUP(YEAR(A10), Lookup!$K:$M, 3) ), B10=55, IF(Z9 >= AD10, Z9 - AD10, 0), B10>55, 0 ) -> 6338.528 | AA10: =IFS( B10<65, IF(AA9+J10 < VLOOKUP(YEAR(A10), Lookup!$Q:$R, 2), AA9 + IF(MONTH(A10)=12, R9+X9, 0) + J10, MIN( AA9 + IF(MONTH(A10)=12, R9+X9, 0) + J10 , VLOOKUP(YEAR(A10), Lookup!$Q:$R, 2) ) ), B10>=65, IF(AA9+J10 < VLOOKUP(questions!$C$5, Lookup!$Q:$R, 2), AA9 + IF(MONTH(A10)=12, R9+X9, 0) + J10 , MIN( AA9 + IF(MONTH(A10)=12, R9+X9, 0) + J10, VLOOKUP(questions!$C$5, Lookup!$Q:$R, 2) ) ) ) -> 7619.616 | AB10: =IFS( B10<55, 0, B10=55, MIN(Y9+Z9, AD10), B10>55, IF(AB9 < $AH$7, MIN(AB9 + IF(MONTH(A10)=12, Q10+W10, 0) + K10, $AH$7), AB9 + IF(MONTH(A10)=12, Q10+W10, 0) + K10 ) ) -> 0 | AC10: {=IFS(B10<66, XLOOKUP(year(A10),Lookup!$K$13:$K1000,Lookup!$L$13:$L1000,"missing",,1),B10>65,XLOOKUP(questions!$C$5,Lookup!$K$13:$K1000,Lookup!$L$13:$L1000,"missing",,1))} -> 110200 | AD10: {=IFS(B10<66, XLOOKUP(year(A10),Lookup!$K$13:$K1000,Lookup!$M$13:$M1000,"missing",,1),B10>65, XLOOKUP(questions!$C$5,Lookup!$K$13:$K1000,Lookup!$M$13:$M1000,"missing",,1))} -> 220400 | AE10: {=IFS(B10<66, XLOOKUP(year(A10),Lookup!$K$13:$K1000,Lookup!$N$13:$N1000,"missing",,1),B10>65,XLOOKUP(questions!$C$5,Lookup!$K$13:$K1000,Lookup!$N$13:$N1000,"missing",,1))} -> 440800
A11: =eomonth(EDATE(A10,1),0) -> 46356 | B11: =round(YEARFRAC(EOMONTH(questions!$C$3, 0),A11,1),2) -> 28 | C11: =IF(B11<questions!$C$6,if(MONTH(A11)=1,C10*(1+questions!$C$12),C10),0) -> 10000 | D11: =IF(MONTH(A11)=12,C11*questions!$C$11,0) -> 0 | E11: =MIN(C11,IF(YEAR(A11)=2025,7600,8000)) -> 8000 | F11: =MIN(102000-E11*12,D11) -> 0 | G11: {=if(YEAR(A11)=2025,XLOOKUP(B11,Lookup!$A$3:$A$7,Lookup!$D$3:$D$7,,1)*SUM(E11:F11), XLOOKUP(B11,Lookup!$A$14:$A$18,Lookup!$D$14:$D$18,,1)*SUM(E11:F11))} -> 2960 | H11: {=if(YEAR(A11)=2025,XLOOKUP(B11,Lookup!$F$3:$F$10,Lookup!$G$3:$G$10,,1)*G11, XLOOKUP(B11,Lookup!$F$14:$F$21,Lookup!$G$14:$G$21,,1)*G11)} -> 1840.232 | I11: {=if(B11<55, if(YEAR(A11)=2025,XLOOKUP(B11,Lookup!$F$3:$F$10,Lookup!$H$3:$H$10,,1)*G11, XLOOKUP(B11,Lookup!$F$14:$F$21,Lookup!$H$14:$H$21,,1)*G11),0)} -> 479.816 | J11: {=if(YEAR(A11)=2025,XLOOKUP(B11,Lookup!$F$3:$F$10,Lookup!$I$3:$I$10,,1)*G11, XLOOKUP(B11,Lookup!$F$14:$F$21,Lookup!$I$14:$I$21,,1)*G11)} -> 639.952 | K11: {=if(B11>54, if(YEAR(A11)=2025,XLOOKUP(B11,Lookup!$F$3:$F$10,Lookup!$H$3:$H$10,,1)*G11, XLOOKUP(B11,Lookup!$F$14:$F$21,Lookup!$H$14:$H$21,,1)*G11),0)} -> 0 | L11: =IF(and(A11<questions!$C$19,questions!$C$18="yes"),questions!$C$20,0) -> 700 | M11: =(Y10+H11)*Lookup!A$26/12 -> 38.462683 | N11: =if(B11<55, (Z10+I11)*Lookup!B$26/12, (AB10+K11)*Lookup!B$26/12) -> 22.727813 | O11: =(AA10+J11)*Lookup!C$26/12 -> 27.531893 | P11: =IF(year(A11)=year(A10), P10+M11, M11) -> 260.64675 | Q11: =IF(year(A11)=year(A10), Q10+N11, N11) -> 146.9724 | R11: =IF(year(A11)=year(A10), R10+O11, O11) -> 170.9928 | S11: =if(B11<55,min(20000,Y10)*0.01/12,min(20000,Y10)*0.02/12) -> 13.851547 | T11: =if(B11<=55,min(60000-min(20000,Y10),Z10)*0.01/12,min(30000-min(20000,Y10),AB10)*0.02/12+min(30000,AB10)*0.01/12) -> 5.2821067 | U11: =if(B11<55,min(60000-min(60000-min(20000,Y10),Z10)-min(20000,Y10),AA10)*0.01/12,min(30000-min(30000-min(20000,Y10),AB10)-min(20000,Y10),AA10)*0.02/12+min(30000-min(30000-min(20000,Y10),AB10)-min(20000,Y10),AA10)*0.01/12) -> 6.34968 | V11: =IF(year($A11)=year($A10), V10+S11, S11) -> 90.45696 | W11: =IF(year($A11)=year($A10), W10+T11, T11) -> 33.14448 | X11: =IF(year($A11)=year($A10), X10+U11, U11) -> 37.94856 | Y11: =IFS( B11<55, MAX( Y10 + IF(MONTH(A11)=12, P11+V11, 0) + H11 - L11 + MAX(0, IF(AA10 >= VLOOKUP(YEAR(A11), Lookup!$Q:$R, 2), Z10 + IF(MONTH(A11)=12, Q11+W11, 0) + I11 + AA10 + IF(MONTH(A11)=12, R11+X11, 0) - VLOOKUP(YEAR(A11), Lookup!$Q:$R, 2) + J11, Z10 + IF(MONTH(A11)=12, Q11+W11, 0) + I11 ) - VLOOKUP(YEAR(A11), Lookup!$K:$M, 3) ), 0), B11=55, IF(Z10>=AD11, MAX(Y10 + IF(MONTH(A11)=12, P11+V11, 0) + H11 - L11, 0), MAX(MAX(0, Y10-(AD11-Z10)) + IF(MONTH(A11)=12, P11+V11, 0) + H11 - L11, 0) ), B11>55, IF(AB10>=$AH$7, MAX(Y10 + IF(MONTH(A11)=12, P11+V11, 0) + H11 - L11 + K11 + Z10, 0), MAX(Y10 + IF(MONTH(A11)=12, P11+V11, 0) + H11 - L11, 0) ) ) -> 17762.088 | Z11: =IFS( B11<55, MIN( IF(AA10 >= VLOOKUP(YEAR(A11), Lookup!$Q:$R, 2), Z10 + IF(MONTH(A11)=12, Q11+W11, 0) + I11 + AA10 + IF(MONTH(A11)=12, R11+X11, 0) - VLOOKUP(YEAR(A11), Lookup!$Q:$R, 2) + J11, Z10 + IF(MONTH(A11)=12, Q11+W11, 0) + I11 ), VLOOKUP(YEAR(A11), Lookup!$K:$M, 3) ), B11=55, IF(Z10 >= AD11, Z10 - AD11, 0), B11>55, 0 ) -> 6818.344 | AA11: =IFS( B11<65, IF(AA10+J11 < VLOOKUP(YEAR(A11), Lookup!$Q:$R, 2), AA10 + IF(MONTH(A11)=12, R10+X10, 0) + J11, MIN( AA10 + IF(MONTH(A11)=12, R10+X10, 0) + J11 , VLOOKUP(YEAR(A11), Lookup!$Q:$R, 2) ) ), B11>=65, IF(AA10+J11 < VLOOKUP(questions!$C$5, Lookup!$Q:$R, 2), AA10 + IF(MONTH(A11)=12, R10+X10, 0) + J11 , MIN( AA10 + IF(MONTH(A11)=12, R10+X10, 0) + J11, VLOOKUP(questions!$C$5, Lookup!$Q:$R, 2) ) ) ) -> 8259.568 | AB11: =IFS( B11<55, 0, B11=55, MIN(Y10+Z10, AD11), B11>55, IF(AB10 < $AH$7, MIN(AB10 + IF(MONTH(A11)=12, Q11+W11, 0) + K11, $AH$7), AB10 + IF(MONTH(A11)=12, Q11+W11, 0) + K11 ) ) -> 0 | AC11: {=IFS(B11<66, XLOOKUP(year(A11),Lookup!$K$13:$K1000,Lookup!$L$13:$L1000,"missing",,1),B11>65,XLOOKUP(questions!$C$5,Lookup!$K$13:$K1000,Lookup!$L$13:$L1000,"missing",,1))} -> 110200 | AD11: {=IFS(B11<66, XLOOKUP(year(A11),Lookup!$K$13:$K1000,Lookup!$M$13:$M1000,"missing",,1),B11>65, XLOOKUP(questions!$C$5,Lookup!$K$13:$K1000,Lookup!$M$13:$M1000,"missing",,1))} -> 220400 | AE11: {=IFS(B11<66, XLOOKUP(year(A11),Lookup!$K$13:$K1000,Lookup!$N$13:$N1000,"missing",,1),B11>65,XLOOKUP(questions!$C$5,Lookup!$K$13:$K1000,Lookup!$N$13:$N1000,"missing",,1))} -> 440800
A12: =eomonth(EDATE(A11,1),0) -> 46387 | B12: =round(YEARFRAC(EOMONTH(questions!$C$3, 0),A12,1),2) -> 28.08 | C12: =IF(B12<questions!$C$6,if(MONTH(A12)=1,C11*(1+questions!$C$12),C11),0) -> 10000 | D12: =IF(MONTH(A12)=12,C12*questions!$C$11,0) -> 10000 | E12: =MIN(C12,IF(YEAR(A12)=2025,7600,8000)) -> 8000 | F12: =MIN(102000-E12*12,D12) -> 6000 | G12: {=if(YEAR(A12)=2025,XLOOKUP(B12,Lookup!$A$3:$A$7,Lookup!$D$3:$D$7,,1)*SUM(E12:F12), XLOOKUP(B12,Lookup!$A$14:$A$18,Lookup!$D$14:$D$18,,1)*SUM(E12:F12))} -> 5180 | H12: {=if(YEAR(A12)=2025,XLOOKUP(B12,Lookup!$F$3:$F$10,Lookup!$G$3:$G$10,,1)*G12, XLOOKUP(B12,Lookup!$F$14:$F$21,Lookup!$G$14:$G$21,,1)*G12)} -> 3220.406 | I12: {=if(B12<55, if(YEAR(A12)=2025,XLOOKUP(B12,Lookup!$F$3:$F$10,Lookup!$H$3:$H$10,,1)*G12, XLOOKUP(B12,Lookup!$F$14:$F$21,Lookup!$H$14:$H$21,,1)*G12),0)} -> 839.678 | J12: {=if(YEAR(A12)=2025,XLOOKUP(B12,Lookup!$F$3:$F$10,Lookup!$I$3:$I$10,,1)*G12, XLOOKUP(B12,Lookup!$F$14:$F$21,Lookup!$I$14:$I$21,,1)*G12)} -> 1119.916 | K12: {=if(B12>54, if(YEAR(A12)=2025,XLOOKUP(B12,Lookup!$F$3:$F$10,Lookup!$H$3:$H$10,,1)*G12, XLOOKUP(B12,Lookup!$F$14:$F$21,Lookup!$H$14:$H$21,,1)*G12),0)} -> 0 | L12: =IF(and(A12<questions!$C$19,questions!$C$18="yes"),questions!$C$20,0) -> 700 | M12: =(Y11+H12)*Lookup!A$26/12 -> 43.713529 | N12: =if(B12<55, (Z11+I12)*Lookup!B$26/12, (AB11+K12)*Lookup!B$26/12) -> 25.52674 | O12: =(AA11+J12)*Lookup!C$26/12 -> 31.264947 | P12: =IF(year(A12)=year(A11), P11+M12, M12) -> 304.36028 | Q12: =IF(year(A12)=year(A11), Q11+N12, N12) -> 172.49914 | R12: =IF(year(A12)=year(A11), R11+O12, O12) -> 202.25775 | S12: =if(B12<55,min(20000,Y11)*0.01/12,min(20000,Y11)*0.02/12) -> 14.80174 | T12: =if(B12<=55,min(60000-min(20000,Y11),Z11)*0.01/12,min(30000-min(20000,Y11),AB11)*0.02/12+min(30000,AB11)*0.01/12) -> 5.6819533 | U12: =if(B12<55,min(60000-min(60000-min(20000,Y11),Z11)-min(20000,Y11),AA11)*0.01/12,min(30000-min(30000-min(20000,Y11),AB11)-min(20000,Y11),AA11)*0.02/12+min(30000-min(30000-min(20000,Y11),AB11)-min(20000,Y11),AA11)*0.01/12) -> 6.8829733 | V12: =IF(year($A12)=year($A11), V11+S12, S12) -> 105.2587 | W12: =IF(year($A12)=year($A11), W11+T12, T12) -> 38.826433 | X12: =IF(year($A12)=year($A11), X11+U12, U12) -> 44.831533 | Y12: =IFS( B12<55, MAX( Y11 + IF(MONTH(A12)=12, P12+V12, 0) + H12 - L12 + MAX(0, IF(AA11 >= VLOOKUP(YEAR(A12), Lookup!$Q:$R, 2), Z11 + IF(MONTH(A12)=12, Q12+W12, 0) + I12 + AA11 + IF(MONTH(A12)=12, R12+X12, 0) - VLOOKUP(YEAR(A12), Lookup!$Q:$R, 2) + J12, Z11 + IF(MONTH(A12)=12, Q12+W12, 0) + I12 ) - VLOOKUP(YEAR(A12), Lookup!$K:$M, 3) ), 0), B12=55, IF(Z11>=AD12, MAX(Y11 + IF(MONTH(A12)=12, P12+V12, 0) + H12 - L12, 0), MAX(MAX(0, Y11-(AD12-Z11)) + IF(MONTH(A12)=12, P12+V12, 0) + H12 - L12, 0) ), B12>55, IF(AB11>=$AH$7, MAX(Y11 + IF(MONTH(A12)=12, P12+V12, 0) + H12 - L12 + K12 + Z11, 0), MAX(Y11 + IF(MONTH(A12)=12, P12+V12, 0) + H12 - L12, 0) ) ) -> 20692.113 | Z12: =IFS( B12<55, MIN( IF(AA11 >= VLOOKUP(YEAR(A12), Lookup!$Q:$R, 2), Z11 + IF(MONTH(A12)=12, Q12+W12, 0) + I12 + AA11 + IF(MONTH(A12)=12, R12+X12, 0) - VLOOKUP(YEAR(A12), Lookup!$Q:$R, 2) + J12, Z11 + IF(MONTH(A12)=12, Q12+W12, 0) + I12 ), VLOOKUP(YEAR(A12), Lookup!$K:$M, 3) ), B12=55, IF(Z11 >= AD12, Z11 - AD12, 0), B12>55, 0 ) -> 7869.3476 | AA12: =IFS( B12<65, IF(AA11+J12 < VLOOKUP(YEAR(A12), Lookup!$Q:$R, 2), AA11 + IF(MONTH(A12)=12, R11+X11, 0) + J12, MIN( AA11 + IF(MONTH(A12)=12, R11+X11, 0) + J12 , VLOOKUP(YEAR(A12), Lookup!$Q:$R, 2) ) ), B12>=65, IF(AA11+J12 < VLOOKUP(questions!$C$5, Lookup!$Q:$R, 2), AA11 + IF(MONTH(A12)=12, R11+X11, 0) + J12 , MIN( AA11 + IF(MONTH(A12)=12, R11+X11, 0) + J12, VLOOKUP(questions!$C$5, Lookup!$Q:$R, 2) ) ) ) -> 9588.4254 | AB12: =IFS( B12<55, 0, B12=55, MIN(Y11+Z11, AD12), B12>55, IF(AB11 < $AH$7, MIN(AB11 + IF(MONTH(A12)=12, Q12+W12, 0) + K12, $AH$7), AB11 + IF(MONTH(A12)=12, Q12+W12, 0) + K12 ) ) -> 0 | AC12: {=IFS(B12<66, XLOOKUP(year(A12),Lookup!$K$13:$K1000,Lookup!$L$13:$L1000,"missing",,1),B12>65,XLOOKUP(questions!$C$5,Lookup!$K$13:$K1000,Lookup!$L$13:$L1000,"missing",,1))} -> 110200 | AD12: {=IFS(B12<66, XLOOKUP(year(A12),Lookup!$K$13:$K1000,Lookup!$M$13:$M1000,"missing",,1),B12>65, XLOOKUP(questions!$C$5,Lookup!$K$13:$K1000,Lookup!$M$13:$M1000,"missing",,1))} -> 220400 | AE12: {=IFS(B12<66, XLOOKUP(year(A12),Lookup!$K$13:$K1000,Lookup!$N$13:$N1000,"missing",,1),B12>65,XLOOKUP(questions!$C$5,Lookup!$K$13:$K1000,Lookup!$N$13:$N1000,"missing",,1))} -> 440800
A13: =eomonth(EDATE(A12,1),0) -> 46418 | B13: =round(YEARFRAC(EOMONTH(questions!$C$3, 0),A13,1),2) -> 28.17 | C13: =IF(B13<questions!$C$6,if(MONTH(A13)=1,C12*(1+questions!$C$12),C12),0) -> 10300 | D13: =IF(MONTH(A13)=12,C13*questions!$C$11,0) -> 0 | E13: =MIN(C13,IF(YEAR(A13)=2025,7600,8000)) -> 8000 | F13: =MIN(102000-E13*12,D13) -> 0 | G13: {=if(YEAR(A13)=2025,XLOOKUP(B13,Lookup!$A$3:$A$7,Lookup!$D$3:$D$7,,1)*SUM(E13:F13), XLOOKUP(B13,Lookup!$A$14:$A$18,Lookup!$D$14:$D$18,,1)*SUM(E13:F13))} -> 2960 | H13: {=if(YEAR(A13)=2025,XLOOKUP(B13,Lookup!$F$3:$F$10,Lookup!$G$3:$G$10,,1)*G13, XLOOKUP(B13,Lookup!$F$14:$F$21,Lookup!$G$14:$G$21,,1)*G13)} -> 1840.232 | I13: {=if(B13<55, if(YEAR(A13)=2025,XLOOKUP(B13,Lookup!$F$3:$F$10,Lookup!$H$3:$H$10,,1)*G13, XLOOKUP(B13,Lookup!$F$14:$F$21,Lookup!$H$14:$H$21,,1)*G13),0)} -> 479.816 | J13: {=if(YEAR(A13)=2025,XLOOKUP(B13,Lookup!$F$3:$F$10,Lookup!$I$3:$I$10,,1)*G13, XLOOKUP(B13,Lookup!$F$14:$F$21,Lookup!$I$14:$I$21,,1)*G13)} -> 639.952 | K13: {=if(B13>54, if(YEAR(A13)=2025,XLOOKUP(B13,Lookup!$F$3:$F$10,Lookup!$H$3:$H$10,,1)*G13, XLOOKUP(B13,Lookup!$F$14:$F$21,Lookup!$H$14:$H$21,,1)*G13),0)} -> 0 | L13: =IF(and(A13<questions!$C$19,questions!$C$18="yes"),questions!$C$20,0) -> 700 | M13: =(Y12+H13)*Lookup!A$26/12 -> 46.942385 | N13: =if(B13<55, (Z12+I13)*Lookup!B$26/12, (AB12+K13)*Lookup!B$26/12) -> 27.830545 | O13: =(AA12+J13)*Lookup!C$26/12 -> 34.094591 | P13: =IF(year(A13)=year(A12), P12+M13, M13) -> 46.942385 | Q13: =IF(year(A13)=year(A12), Q12+N13, N13) -> 27.830545 | R13: =IF(year(A13)=year(A12), R12+O13, O13) -> 34.094591 | S13: =if(B13<55,min(20000,Y12)*0.01/12,min(20000,Y12)*0.02/12) -> 16.666667 | T13: =if(B13<=55,min(60000-min(20000,Y12),Z12)*0.01/12,min(30000-min(20000,Y12),AB12)*0.02/12+min(30000,AB12)*0.01/12) -> 6.5577896 | U13: =if(B13<55,min(60000-min(60000-min(20000,Y12),Z12)-min(20000,Y12),AA12)*0.01/12,min(30000-min(30000-min(20000,Y12),AB12)-min(20000,Y12),AA12)*0.02/12+min(30000-min(30000-min(20000,Y12),AB12)-min(20000,Y12),AA12)*0.01/12) -> 7.9903545 | V13: =IF(year($A13)=year($A12), V12+S13, S13) -> 16.666667 | W13: =IF(year($A13)=year($A12), W12+T13, T13) -> 6.5577896 | X13: =IF(year($A13)=year($A12), X12+U13, U13) -> 7.9903545 | Y13: =IFS( B13<55, MAX( Y12 + IF(MONTH(A13)=12, P13+V13, 0) + H13 - L13 + MAX(0, IF(AA12 >= VLOOKUP(YEAR(A13), Lookup!$Q:$R, 2), Z12 + IF(MONTH(A13)=12, Q13+W13, 0) + I13 + AA12 + IF(MONTH(A13)=12, R13+X13, 0) - VLOOKUP(YEAR(A13), Lookup!$Q:$R, 2) + J13, Z12 + IF(MONTH(A13)=12, Q13+W13, 0) + I13 ) - VLOOKUP(YEAR(A13), Lookup!$K:$M, 3) ), 0), B13=55, IF(Z12>=AD13, MAX(Y12 + IF(MONTH(A13)=12, P13+V13, 0) + H13 - L13, 0), MAX(MAX(0, Y12-(AD13-Z12)) + IF(MONTH(A13)=12, P13+V13, 0) + H13 - L13, 0) ), B13>55, IF(AB12>=$AH$7, MAX(Y12 + IF(MONTH(A13)=12, P13+V13, 0) + H13 - L13 + K13 + Z12, 0), MAX(Y12 + IF(MONTH(A13)=12, P13+V13, 0) + H13 - L13, 0) ) ) -> 21832.345 | Z13: =IFS( B13<55, MIN( IF(AA12 >= VLOOKUP(YEAR(A13), Lookup!$Q:$R, 2), Z12 + IF(MONTH(A13)=12, Q13+W13, 0) + I13 + AA12 + IF(MONTH(A13)=12, R13+X13, 0) - VLOOKUP(YEAR(A13), Lookup!$Q:$R, 2) + J13, Z12 + IF(MONTH(A13)=12, Q13+W13, 0) + I13 ), VLOOKUP(YEAR(A13), Lookup!$K:$M, 3) ), B13=55, IF(Z12 >= AD13, Z12 - AD13, 0), B13>55, 0 ) -> 8349.1636 | AA13: =IFS( B13<65, IF(AA12+J13 < VLOOKUP(YEAR(A13), Lookup!$Q:$R, 2), AA12 + IF(MONTH(A13)=12, R12+X12, 0) + J13, MIN( AA12 + IF(MONTH(A13)=12, R12+X12, 0) + J13 , VLOOKUP(YEAR(A13), Lookup!$Q:$R, 2) ) ), B13>=65, IF(AA12+J13 < VLOOKUP(questions!$C$5, Lookup!$Q:$R, 2), AA12 + IF(MONTH(A13)=12, R12+X12, 0) + J13 , MIN( AA12 + IF(MONTH(A13)=12, R12+X12, 0) + J13, VLOOKUP(questions!$C$5, Lookup!$Q:$R, 2) ) ) ) -> 10228.377 | AB13: =IFS( B13<55, 0, B13=55, MIN(Y12+Z12, AD13), B13>55, IF(AB12 < $AH$7, MIN(AB12 + IF(MONTH(A13)=12, Q13+W13, 0) + K13, $AH$7), AB12 + IF(MONTH(A13)=12, Q13+W13, 0) + K13 ) ) -> 0 | AC13: {=IFS(B13<66, XLOOKUP(year(A13),Lookup!$K$13:$K1000,Lookup!$L$13:$L1000,"missing",,1),B13>65,XLOOKUP(questions!$C$5,Lookup!$K$13:$K1000,Lookup!$L$13:$L1000,"missing",,1))} -> 114100 | AD13: {=IFS(B13<66, XLOOKUP(year(A13),Lookup!$K$13:$K1000,Lookup!$M$13:$M1000,"missing",,1),B13>65, XLOOKUP(questions!$C$5,Lookup!$K$13:$K1000,Lookup!$M$13:$M1000,"missing",,1))} -> 228200 | AE13: {=IFS(B13<66, XLOOKUP(year(A13),Lookup!$K$13:$K1000,Lookup!$N$13:$N1000,"missing",,1),B13>65,XLOOKUP(questions!$C$5,Lookup!$K$13:$K1000,Lookup!$N$13:$N1000,"missing",,1))} -> 456400
A14: =eomonth(EDATE(A13,1),0) -> 46446 | B14: =round(YEARFRAC(EOMONTH(questions!$C$3, 0),A14,1),2) -> 28.25 | C14: =IF(B14<questions!$C$6,if(MONTH(A14)=1,C13*(1+questions!$C$12),C13),0) -> 10300 | D14: =IF(MONTH(A14)=12,C14*questions!$C$11,0) -> 0 | E14: =MIN(C14,IF(YEAR(A14)=2025,7600,8000)) -> 8000 | F14: =MIN(102000-E14*12,D14) -> 0 | G14: {=if(YEAR(A14)=2025,XLOOKUP(B14,Lookup!$A$3:$A$7,Lookup!$D$3:$D$7,,1)*SUM(E14:F14), XLOOKUP(B14,Lookup!$A$14:$A$18,Lookup!$D$14:$D$18,,1)*SUM(E14:F14))} -> 2960 | H14: {=if(YEAR(A14)=2025,XLOOKUP(B14,Lookup!$F$3:$F$10,Lookup!$G$3:$G$10,,1)*G14, XLOOKUP(B14,Lookup!$F$14:$F$21,Lookup!$G$14:$G$21,,1)*G14)} -> 1840.232 | I14: {=if(B14<55, if(YEAR(A14)=2025,XLOOKUP(B14,Lookup!$F$3:$F$10,Lookup!$H$3:$H$10,,1)*G14, XLOOKUP(B14,Lookup!$F$14:$F$21,Lookup!$H$14:$H$21,,1)*G14),0)} -> 479.816 | J14: {=if(YEAR(A14)=2025,XLOOKUP(B14,Lookup!$F$3:$F$10,Lookup!$I$3:$I$10,,1)*G14, XLOOKUP(B14,Lookup!$F$14:$F$21,Lookup!$I$14:$I$21,,1)*G14)} -> 639.952 | K14: {=if(B14>54, if(YEAR(A14)=2025,XLOOKUP(B14,Lookup!$F$3:$F$10,Lookup!$H$3:$H$10,,1)*G14, XLOOKUP(B14,Lookup!$F$14:$F$21,Lookup!$H$14:$H$21,,1)*G14),0)} -> 0 | L14: =IF(and(A14<questions!$C$19,questions!$C$18="yes"),questions!$C$20,0) -> 700 | M14: =(Y13+H14)*Lookup!A$26/12 -> 49.317869 | N14: =if(B14<55, (Z13+I14)*Lookup!B$26/12, (AB13+K14)*Lookup!B$26/12) -> 29.429932 | O14: =(AA13+J14)*Lookup!C$26/12 -> 36.227765 | P14: =IF(year(A14)=year(A13), P13+M14, M14) -> 96.260254 | Q14: =IF(year(A14)=year(A13), Q13+N14, N14) -> 57.260477 | R14: =IF(year(A14)=year(A13), R13+O14, O14) -> 70.322356 | S14: =if(B14<55,min(20000,Y13)*0.01/12,min(20000,Y13)*0.02/12) -> 16.666667 | T14: =if(B14<=55,min(60000-min(20000,Y13),Z13)*0.01/12,min(30000-min(20000,Y13),AB13)*0.02/12+min(30000,AB13)*0.01/12) -> 6.9576363 | U14: =if(B14<55,min(60000-min(60000-min(20000,Y13),Z13)-min(20000,Y13),AA13)*0.01/12,min(30000-min(30000-min(20000,Y13),AB13)-min(20000,Y13),AA13)*0.02/12+min(30000-min(30000-min(20000,Y13),AB13)-min(20000,Y13),AA13)*0.01/12) -> 8.5236478 | V14: =IF(year($A14)=year($A13), V13+S14, S14) -> 33.333333 | W14: =IF(year($A14)=year($A13), W13+T14, T14) -> 13.515426 | X14: =IF(year($A14)=year($A13), X13+U14, U14) -> 16.514002 | Y14: =IFS( B14<55, MAX( Y13 + IF(MONTH(A14)=12, P14+V14, 0) + H14 - L14 + MAX(0, IF(AA13 >= VLOOKUP(YEAR(A14), Lookup!$Q:$R, 2), Z13 + IF(MONTH(A14)=12, Q14+W14, 0) + I14 + AA13 + IF(MONTH(A14)=12, R14+X14, 0) - VLOOKUP(YEAR(A14), Lookup!$Q:$R, 2) + J14, Z13 + IF(MONTH(A14)=12, Q14+W14, 0) + I14 ) - VLOOKUP(YEAR(A14), Lookup!$K:$M, 3) ), 0), B14=55, IF(Z13>=AD14, MAX(Y13 + IF(MONTH(A14)=12, P14+V14, 0) + H14 - L14, 0), MAX(MAX(0, Y13-(AD14-Z13)) + IF(MONTH(A14)=12, P14+V14, 0) + H14 - L14, 0) ), B14>55, IF(AB13>=$AH$7, MAX(Y13 + IF(MONTH(A14)=12, P14+V14, 0) + H14 - L14 + K14 + Z13, 0), MAX(Y13 + IF(MONTH(A14)=12, P14+V14, 0) + H14 - L14, 0) ) ) -> 22972.577 | Z14: =IFS( B14<55, MIN( IF(AA13 >= VLOOKUP(YEAR(A14), Lookup!$Q:$R, 2), Z13 + IF(MONTH(A14)=12, Q14+W14, 0) + I14 + AA13 + IF(MONTH(A14)=12, R14+X14, 0) - VLOOKUP(YEAR(A14), Lookup!$Q:$R, 2) + J14, Z13 + IF(MONTH(A14)=12, Q14+W14, 0) + I14 ), VLOOKUP(YEAR(A14), Lookup!$K:$M, 3) ), B14=55, IF(Z13 >= AD14, Z13 - AD14, 0), B14>55, 0 ) -> 8828.9796 | AA14: =IFS( B14<65, IF(AA13+J14 < VLOOKUP(YEAR(A14), Lookup!$Q:$R, 2), AA13 + IF(MONTH(A14)=12, R13+X13, 0) + J14, MIN( AA13 + IF(MONTH(A14)=12, R13+X13, 0) + J14 , VLOOKUP(YEAR(A14), Lookup!$Q:$R, 2) ) ), B14>=65, IF(AA13+J14 < VLOOKUP(questions!$C$5, Lookup!$Q:$R, 2), AA13 + IF(MONTH(A14)=12, R13+X13, 0) + J14 , MIN( AA13 + IF(MONTH(A14)=12, R13+X13, 0) + J14, VLOOKUP(questions!$C$5, Lookup!$Q:$R, 2) ) ) ) -> 10868.329 | AB14: =IFS( B14<55, 0, B14=55, MIN(Y13+Z13, AD14), B14>55, IF(AB13 < $AH$7, MIN(AB13 + IF(MONTH(A14)=12, Q14+W14, 0) + K14, $AH$7), AB13 + IF(MONTH(A14)=12, Q14+W14, 0) + K14 ) ) -> 0 | AC14: {=IFS(B14<66, XLOOKUP(year(A14),Lookup!$K$13:$K1000,Lookup!$L$13:$L1000,"missing",,1),B14>65,XLOOKUP(questions!$C$5,Lookup!$K$13:$K1000,Lookup!$L$13:$L1000,"missing",,1))} -> 114100 | AD14: {=IFS(B14<66, XLOOKUP(year(A14),Lookup!$K$13:$K1000,Lookup!$M$13:$M1000,"missing",,1),B14>65, XLOOKUP(questions!$C$5,Lookup!$K$13:$K1000,Lookup!$M$13:$M1000,"missing",,1))} -> 228200 | AE14: {=IFS(B14<66, XLOOKUP(year(A14),Lookup!$K$13:$K1000,Lookup!$N$13:$N1000,"missing",,1),B14>65,XLOOKUP(questions!$C$5,Lookup!$K$13:$K1000,Lookup!$N$13:$N1000,"missing",,1))} -> 456400
A15: =eomonth(EDATE(A14,1),0) -> 46477 | B15: =round(YEARFRAC(EOMONTH(questions!$C$3, 0),A15,1),2) -> 28.33 | C15: =IF(B15<questions!$C$6,if(MONTH(A15)=1,C14*(1+questions!$C$12),C14),0) -> 10300 | D15: =IF(MONTH(A15)=12,C15*questions!$C$11,0) -> 0 | E15: =MIN(C15,IF(YEAR(A15)=2025,7600,8000)) -> 8000 | F15: =MIN(102000-E15*12,D15) -> 0 | G15: {=if(YEAR(A15)=2025,XLOOKUP(B15,Lookup!$A$3:$A$7,Lookup!$D$3:$D$7,,1)*SUM(E15:F15), XLOOKUP(B15,Lookup!$A$14:$A$18,Lookup!$D$14:$D$18,,1)*SUM(E15:F15))} -> 2960 | H15: {=if(YEAR(A15)=2025,XLOOKUP(B15,Lookup!$F$3:$F$10,Lookup!$G$3:$G$10,,1)*G15, XLOOKUP(B15,Lookup!$F$14:$F$21,Lookup!$G$14:$G$21,,1)*G15)} -> 1840.232 | I15: {=if(B15<55, if(YEAR(A15)=2025,XLOOKUP(B15,Lookup!$F$3:$F$10,Lookup!$H$3:$H$10,,1)*G15, XLOOKUP(B15,Lookup!$F$14:$F$21,Lookup!$H$14:$H$21,,1)*G15),0)} -> 479.816 | J15: {=if(YEAR(A15)=2025,XLOOKUP(B15,Lookup!$F$3:$F$10,Lookup!$I$3:$I$10,,1)*G15, XLOOKUP(B15,Lookup!$F$14:$F$21,Lookup!$I$14:$I$21,,1)*G15)} -> 639.952 | K15: {=if(B15>54, if(YEAR(A15)=2025,XLOOKUP(B15,Lookup!$F$3:$F$10,Lookup!$H$3:$H$10,,1)*G15, XLOOKUP(B15,Lookup!$F$14:$F$21,Lookup!$H$14:$H$21,,1)*G15),0)} -> 0 | L15: =IF(and(A15<questions!$C$19,questions!$C$18="yes"),questions!$C$20,0) -> 700 | M15: =(Y14+H15)*Lookup!A$26/12 -> 51.693352 | N15: =if(B15<55, (Z14+I15)*Lookup!B$26/12, (AB14+K15)*Lookup!B$26/12) -> 31.029319 | O15: =(AA14+J15)*Lookup!C$26/12 -> 38.360938 | P15: =IF(year(A15)=year(A14), P14+M15, M15) -> 147.95361 | Q15: =IF(year(A15)=year(A14), Q14+N15, N15) -> 88.289796 | R15: =IF(year(A15)=year(A14), R14+O15, O15) -> 108.68329 | S15: =if(B15<55,min(20000,Y14)*0.01/12,min(20000,Y14)*0.02/12) -> 16.666667 | T15: =if(B15<=55,min(60000-min(20000,Y14),Z14)*0.01/12,min(30000-min(20000,Y14),AB14)*0.02/12+min(30000,AB14)*0.01/12) -> 7.357483 | U15: =if(B15<55,min(60000-min(60000-min(20000,Y14),Z14)-min(20000,Y14),AA14)*0.01/12,min(30000-min(30000-min(20000,Y14),AB14)-min(20000,Y14),AA14)*0.02/12+min(30000-min(30000-min(20000,Y14),AB14)-min(20000,Y14),AA14)*0.01/12) -> 9.0569411 | V15: =IF(year($A15)=year($A14), V14+S15, S15) -> 50 | W15: =IF(year($A15)=year($A14), W14+T15, T15) -> 20.872909 | X15: =IF(year($A15)=year($A14), X14+U15, U15) -> 25.570943 | Y15: =IFS( B15<55, MAX( Y14 + IF(MONTH(A15)=12, P15+V15, 0) + H15 - L15 + MAX(0, IF(AA14 >= VLOOKUP(YEAR(A15), Lookup!$Q:$R, 2), Z14 + IF(MONTH(A15)=12, Q15+W15, 0) + I15 + AA14 + IF(MONTH(A15)=12, R15+X15, 0) - VLOOKUP(YEAR(A15), Lookup!$Q:$R, 2) + J15, Z14 + IF(MONTH(A15)=12, Q15+W15, 0) + I15 ) - VLOOKUP(YEAR(A15), Lookup!$K:$M, 3) ), 0), B15=55, IF(Z14>=AD15, MAX(Y14 + IF(MONTH(A15)=12, P15+V15, 0) + H15 - L15, 0), MAX(MAX(0, Y14-(AD15-Z14)) + IF(MONTH(A15)=12, P15+V15, 0) + H15 - L15, 0) ), B15>55, IF(AB14>=$AH$7, MAX(Y14 + IF(MONTH(A15)=12, P15+V15, 0) + H15 - L15 + K15 + Z14, 0), MAX(Y14 + IF(MONTH(A15)=12, P15+V15, 0) + H15 - L15, 0) ) ) -> 24112.809 | Z15: =IFS( B15<55, MIN( IF(AA14 >= VLOOKUP(YEAR(A15), Lookup!$Q:$R, 2), Z14 + IF(MONTH(A15)=12, Q15+W15, 0) + I15 + AA14 + IF(MONTH(A15)=12, R15+X15, 0) - VLOOKUP(YEAR(A15), Lookup!$Q:$R, 2) + J15, Z14 + IF(MONTH(A15)=12, Q15+W15, 0) + I15 ), VLOOKUP(YEAR(A15), Lookup!$K:$M, 3) ), B15=55, IF(Z14 >= AD15, Z14 - AD15, 0), B15>55, 0 ) -> 9308.7956 | AA15: =IFS( B15<65, IF(AA14+J15 < VLOOKUP(YEAR(A15), Lookup!$Q:$R, 2), AA14 + IF(MONTH(A15)=12, R14+X14, 0) + J15, MIN( AA14 + IF(MONTH(A15)=12, R14+X14, 0) + J15 , VLOOKUP(YEAR(A15), Lookup!$Q:$R, 2) ) ), B15>=65, IF(AA14+J15 < VLOOKUP(questions!$C$5, Lookup!$Q:$R, 2), AA14 + IF(MONTH(A15)=12, R14+X14, 0) + J15 , MIN( AA14 + IF(MONTH(A15)=12, R14+X14, 0) + J15, VLOOKUP(questions!$C$5, Lookup!$Q:$R, 2) ) ) ) -> 11508.281 | AB15: =IFS( B15<55, 0, B15=55, MIN(Y14+Z14, AD15), B15>55, IF(AB14 < $AH$7, MIN(AB14 + IF(MONTH(A15)=12, Q15+W15, 0) + K15, $AH$7), AB14 + IF(MONTH(A15)=12, Q15+W15, 0) + K15 ) ) -> 0 | AC15: {=IFS(B15<66, XLOOKUP(year(A15),Lookup!$K$13:$K1000,Lookup!$L$13:$L1000,"missing",,1),B15>65,XLOOKUP(questions!$C$5,Lookup!$K$13:$K1000,Lookup!$L$13:$L1000,"missing",,1))} -> 114100 | AD15: {=IFS(B15<66, XLOOKUP(year(A15),Lookup!$K$13:$K1000,Lookup!$M$13:$M1000,"missing",,1),B15>65, XLOOKUP(questions!$C$5,Lookup!$K$13:$K1000,Lookup!$M$13:$M1000,"missing",,1))} -> 228200 | AE15: {=IFS(B15<66, XLOOKUP(year(A15),Lookup!$K$13:$K1000,Lookup!$N$13:$N1000,"missing",,1),B15>65,XLOOKUP(questions!$C$5,Lookup!$K$13:$K1000,Lookup!$N$13:$N1000,"missing",,1))} -> 456400
